Workbook

Sheet Data
A1: CC NO | B1: OMC | C1: NAME OF THE RO | D1: LOCATION | E1: DISTT | F1: Trading Area for Dealers | G1: Trading Area | H1: Bigger Trading Area | I1: SO Name | J1: MS0424 | K1: MS-0425 | L1: HSD-0424 | M1: HSD-0425 | N1: MS-0524 | O1: MS-0525 | P1: HSD-0524 | Q1: HSD-0525 | R1: MS-0625 | S1: MS-0624 | T1: HSD-0624 | U1: HSD-0625 | V1: MS-0725 | W1: MS-0724 | X1: HSD-0725 | Y1: HSD-0724 | Z1: MS-0825 | AA1: MS-0824 | AB1: HSD-0825 | AC1: HSD-0824 | AD1: MS-0925 | AE1: MS-0924 | AF1: HSD-0925 | AG1: HSD-0924 | AH1: MS-1025 | AI1: MS-1024 | AJ1: HSD-1025 | AK1: HSD-1024 | AL1: MS-1125 | AM1: MS-1124 | AN1: HSD-1125 | AO1: HSD-1124 | AP1: MS-1225 | AQ1: MS-1224 | AR1: HSD-1225 | AS1: HSD-1224 | AT1: MS-0126 | AU1: MS-0125 | AV1: HSD-0126 | AW1: HSD-0125 | AX1: MS-0226 | AY1: MS-0225 | AZ1: HSD-0226 | BA1: HSD-0225 | BB1: MS-0326 | BC1: MS-0325 | BD1: HSD-0326 | BE1: HSD-0325 | BF1: Lattitude | BG1: Longitude | BH1: MS TM TY | BI1: MS TM LY | BJ1: Gain in KL MS TM | BK1: %Gain MS TM | BL1: HSD TMTY | BM1: HSDTMLY | BN1: Gain in KL HSD TM | BO1: %Gain HSD TM | BP1: MSTY | BQ1: MSLY | BR1: Gain in KL MS TY | BS1: %Gain MS TY | BT1: HSDTY | BU1: HSDLY | BV1: Gain in KL HSD TY | BW1: %Gain HSD TY | BX1: Speed TM | BY1: Speed Conversion % TM | BZ1: Speed TY | CA1: Speed Conversion TY | CB1: MS MS TMTY | CC1: MS MS TMLY | CD1: Change in Market Share MS | CE1: HSD MS TMTY | CF1: HSD MS TMLY | CG1: Change in Market Share HSD TM | CH1: MS MS TY | CI1: MS MS LY | CJ1: Change in Market Share MS TY | CK1: HSD MS TY | CL1: HSD MS LY | CM1: Change in Market Share HSD TY | CN1: Effectivity MS Ty | CO1: Effectivity HSD TY | CP1: Growth Feb Vs March | CQ1: reasons
A2: 129151 | B2: BPC | C2: ALLIED MOTORS LTD. | D2: PREET VIHAR DELHI | E2: EAST DELHI | F2: ALLIED_MASIH | G2: ALLIED_MASIH | H2: Mayur Vihar -Anand Vihar -Preet Vihar | I2: Bhanu Pratap | J2: 1004 | K2: 1096 | L2: 186 | M2: 172 | N2: 1057.5 | O2: 1175 | P2: 208.5 | Q2: 175 | R2: 1088 | S2: 1042 | T2: 190 | U2: 186 | V2: 1203 | W2: 1042 | X2: 169 | Y2: 200 | Z2: 1200 | AA2: 1042.5 | AB2: 180 | AC2: 201.5 | AD2: 1157 | AE2: 1092 | AF2: 165 | AG2: 180 | AH2: 1196 | AI2: 1012.5 | AJ2: 168 | AK2: 175.5 | AL2: 1142 | AM2: 1020.5 | AN2: 150 | AO2: 161.5 | AP2: 1100 | AQ2: 990 | AR2: 140 | AS2: 140 | AT2: 1072 | AU2: 963.5 | AV2: 140 | AW2: 164.5 | AX2: 1028 | AY2: 931 | AZ2: 150 | BA2: 163 | BB2: 1197 | BC2: 1008 | BD2: 175 | BE2: 172 | BF2: 28.63971 | BG2: 77.29353 | BH2: =BB2 -> 1197 | BI2: =BC2 -> 1008 | BJ2: =(BH2-BI2) -> 189 | BK2: =(BJ2)/BI2*100 -> 18.75 | BL2: =BD2 -> 175 | BM2: =BE2 -> 172 | BN2: =(BL2-BM2) -> 3 | BO2: =(BN2)/BM2*100 -> 1.744186 | BP2: =K2+O2+R2+V2+Z2+AD2+AH2+AL2+AP2+AT2+AX2+BB2 -> 13654 | BQ2: =J2+N2+S2+W2+AA2+AE2+AI2+AM2+AQ2+AU2+Table1[[#This Row],[MS-0225]]+Table1[[#This Row],[MS-0325]] -> 12205.5 | BR2: =(BP2-BQ2) -> 1448.4999 | BS2: =(BR2)/BQ2*100 -> 11.8676 | BT2: =M2+Q2+T2+X2+AB2+AF2+AJ2+AN2+AR2+AV2+AZ2+BD2 -> 1974 | BU2: =L2+P2+U2+Y2+AC2+AG2+AK2+AO2+AS2+AW2+BA2+BE2 -> 2138.5 | BV2: =(BT2-BU2) -> -164.5 | BW2: =(BV2)/BU2*100 -> -7.6923077 | BX2: 180 | BY2: =BX2/BH2 -> 0.15037594 | BZ2: 1197 | CA2: =BZ2/BP2 -> 0.087666618 | CB2: =BH2/SUMIFS(BH$2:BH$398,G$2:G$398,G2) -> 0.2898656 | CC2: =BI2/SUMIFS(BI$2:BI$398,G$2:G$398,G2) -> 0.26561265 | CD2: =CB2-CC2 -> 0.024252953 | CE2: =BL2/SUMIFS(BL$2:BL$398,G$2:G$398,G2) -> 0.2745098 | CF2: =BM2/SUMIFS(BM$2:BM$398,G$2:G$398,G2) -> 0.25671642 | CG2: =CE2-CF2 -> 0.017793386 | CH2: =BP2/SUMIFS(BP$2:BP$398,G$2:G$398,G2) -> 0.27816037 | CI2: =BQ2/SUMIFS(BQ$2:BQ$398,G$2:G$398,G2) -> 0.26668488 | CJ2: =CH2-CI2 -> 0.011475495 | CK2: =BT2/SUMIFS(BT$2:BT$398,G$2:G$398,G2) -> 0.25436676 | CL2: =BU2/SUMIFS(BU$2:BU$398,G$2:G$398,G2) -> 0.25288539 | CM2: =CK2-CL2 -> 0.0014813736 | CN2: =COUNTIFS(G$2:G$398,G2)*CH2 -> 2.225283 | CO2: =COUNTIFS(G$2:G$398,G2)*CK2 -> 2.0349341
A3: 41030786 | B3: HPC | C3: R D MOTORS | D3: JASOLA | E3: SOUTH EAST DELHI | F3: AUTO REST_OKHLA | G3: AUTO REST_OKHLA | H3: Okhla | I3: Bhanu Pratap | J3: 950 | K3: 974 | L3: 335 | M3: 302 | N3: 1008.5 | O3: 1050.5 | P3: 359.5 | Q3: 329.5 | R3: 1032 | S3: 1007.5 | T3: 307 | U3: 363.5 | V3: 1059.5 | W3: 1027.5 | X3: 309.5 | Y3: 343.5 | Z3: 1082.5 | AA3: 1052 | AB3: 282.5 | AC3: 377 | AD3: 996 | AE3: 1024 | AF3: 283 | AG3: 344 | AH3: 1025 | AI3: 1050 | AJ3: 305 | AK3: 380 | AL3: 1033 | AM3: 937 | AN3: 300 | AO3: 293 | AP3: 969 | AQ3: 932.5 | AR3: 283 | AS3: 288.5 | AT3: 932 | AU3: 885 | AV3: 307 | AW3: 330 | AX3: 969.5 | AY3: 925.5 | AZ3: 303.5 | BA3: 329.5 | BB3: 1091 | BC3: 973 | BD3: 314 | BE3: 315 | BF3: 28.53871 | BG3: 77.29157 | BH3: =BB3 -> 1091 | BI3: =BC3 -> 973 | BJ3: =(BH3-BI3) -> 118 | BK3: =(BJ3)/BI3*100 -> 12.127441 | BL3: =BD3 -> 314 | BM3: =BE3 -> 315 | BN3: =(BL3-BM3) -> -1 | BO3: =(BN3)/BM3*100 -> -0.31746032 | BP3: =K3+O3+R3+V3+Z3+AD3+AH3+AL3+AP3+AT3+AX3+BB3 -> 12214 | BQ3: =J3+N3+S3+W3+AA3+AE3+AI3+AM3+AQ3+AU3+Table1[[#This Row],[MS-0225]]+Table1[[#This Row],[MS-0325]] -> 11772.5 | BR3: =(BP3-BQ3) -> 441.5 | BS3: =(BR3)/BQ3*100 -> 3.7502654 | BT3: =M3+Q3+T3+X3+AB3+AF3+AJ3+AN3+AR3+AV3+AZ3+BD3 -> 3626 | BU3: =L3+P3+U3+Y3+AC3+AG3+AK3+AO3+AS3+AW3+BA3+BE3 -> 4058.5 | BV3: =(BT3-BU3) -> -432.5 | BW3: =(BV3)/BU3*100 -> -10.656647 | BX3: 0 | BY3: =BX3/BH3 -> 0 | BZ3: 0 | CA3: =BZ3/BP3 -> 0 | CB3: =BH3/SUMIFS(BH$2:BH$398,G$2:G$398,G3) -> 0.19818347 | CC3: =BI3/SUMIFS(BI$2:BI$398,G$2:G$398,G3) -> 0.18636277 | CD3: =CB3-CC3 -> 0.011820704 | CE3: =BL3/SUMIFS(BL$2:BL$398,G$2:G$398,G3) -> 0.21820709 | CF3: =BM3/SUMIFS(BM$2:BM$398,G$2:G$398,G3) -> 0.20257235 | CG3: =CE3-CF3 -> 0.015634741 | CH3: =BP3/SUMIFS(BP$2:BP$398,G$2:G$398,G3) -> 0.19019293 | CI3: =BQ3/SUMIFS(BQ$2:BQ$398,G$2:G$398,G3) -> 0.18457257 | CJ3: =CH3-CI3 -> 0.0056203628 | CK3: =BT3/SUMIFS(BT$2:BT$398,G$2:G$398,G3) -> 0.20198307 | CL3: =BU3/SUMIFS(BU$2:BU$398,G$2:G$398,G3) -> 0.1941866 | CM3: =CK3-CL3 -> 0.0077964631 | CN3: =COUNTIFS(G$2:G$398,G3)*CH3 -> 2.0921223 | CO3: =COUNTIFS(G$2:G$398,G3)*CK3 -> 2.2218137
A4: 106330 | B4: IOC | C4: RAJPATH MOTORS | D4: GEETA COLONY, SITE I | E4: EAST DELHI | F4: White Patch_Geeta Colony | G4: White Patch_Geeta Colony | H4: Mayur Vihar -Anand Vihar -Preet Vihar | I4: Bhanu Pratap | J4: 711 | K4: 695.5 | L4: 135 | M4: 120.5 | N4: 728 | O4: 710.5 | P4: 140 | Q4: 103.5 | R4: 646 | S4: 738 | T4: 102 | U4: 126 | V4: 677.5 | W4: 738 | X4: 98.5 | Y4: 126 | Z4: 648 | AA4: 787.5 | AB4: 116 | AC4: 130.5 | AD4: 646 | AE4: 720 | AF4: 92 | AG4: 126 | AH4: 736 | AI4: 821 | AJ4: 98 | AK4: 117 | AL4: 727 | AM4: 717.5 | AN4: 97 | AO4: 112.5 | AP4: 734.5 | AQ4: 688.5 | AR4: 111.5 | AS4: 103.5 | AT4: 788 | AU4: 680 | AV4: 110 | AW4: 118 | AX4: 797.5 | AY4: 638 | AZ4: 128.5 | BA4: 142 | BB4: 959 | BC4: 675 | BD4: 157 | BE4: 99 | BF4: 28.6518 | BG4: 77.2683 | BH4: =BB4 -> 959 | BI4: =BC4 -> 675 | BJ4: =(BH4-BI4) -> 284 | BK4: =(BJ4)/BI4*100 -> 42.074074 | BL4: =BD4 -> 157 | BM4: =BE4 -> 99 | BN4: =(BL4-BM4) -> 58 | BO4: =(BN4)/BM4*100 -> 58.585859 | BP4: =K4+O4+R4+V4+Z4+AD4+AH4+AL4+AP4+AT4+AX4+BB4 -> 8765.5 | BQ4: =J4+N4+S4+W4+AA4+AE4+AI4+AM4+AQ4+AU4+Table1[[#This Row],[MS-0225]]+Table1[[#This Row],[MS-0325]] -> 8642.5 | BR4: =(BP4-BQ4) -> 123 | BS4: =(BR4)/BQ4*100 -> 1.4231993 | BT4: =M4+Q4+T4+X4+AB4+AF4+AJ4+AN4+AR4+AV4+AZ4+BD4 -> 1334.5 | BU4: =L4+P4+U4+Y4+AC4+AG4+AK4+AO4+AS4+AW4+BA4+BE4 -> 1475.5 | BV4: =(BT4-BU4) -> -141 | BW4: =(BV4)/BU4*100 -> -9.5560827 | BX4: 0 | BY4: =BX4/BH4 -> 0 | BZ4: 0 | CA4: =BZ4/BP4 -> 0 | CB4: =BH4/SUMIFS(BH$2:BH$398,G$2:G$398,G4) -> 0.65649004 | CC4: =BI4/SUMIFS(BI$2:BI$398,G$2:G$398,G4) -> 0.58039553 | CD4: =CB4-CC4 -> 0.076094515 | CE4: =BL4/SUMIFS(BL$2:BL$398,G$2:G$398,G4) -> 0.71984338 | CF4: =BM4/SUMIFS(BM$2:BM$398,G$2:G$398,G4) -> 0.64705882 | CG4: =CE4-CF4 -> 0.072784553 | CH4: =BP4/SUMIFS(BP$2:BP$398,G$2:G$398,G4) -> 0.58934363 | CI4: =BQ4/SUMIFS(BQ$2:BQ$398,G$2:G$398,G4) -> 0.60451707 | CJ4: =CH4-CI4 -> -0.015173432 | CK4: =BT4/SUMIFS(BT$2:BT$398,G$2:G$398,G4) -> 0.68991188 | CL4: =BU4/SUMIFS(BU$2:BU$398,G$2:G$398,G4) -> 0.71709585 | CM4: =CK4-CL4 -> -0.027183966 | CN4: =COUNTIFS(G$2:G$398,G4)*CH4 -> 1.1786873 | CO4: =COUNTIFS(G$2:G$398,G4)*CK4 -> 1.3798238
A5: 186841 | B5: IOC | C5: WELCOME MOTORS | D5: SAKET | E5: SOUTH DELHI | F5: White Patch_Saket | G5: White Patch_Saket | H5: Hauj Khas-Saket-Vasant Kunj | I5: Raj Doshi | J5: 877.5 | K5: 886.5 | L5: 166.5 | M5: 157.5 | N5: 962.5 | O5: 954 | P5: 193.5 | Q5: 162 | R5: 874.5 | S5: 953.5 | T5: 139.5 | U5: 184.5 | V5: 958.5 | W5: 1014.5 | X5: 157.5 | Y5: 191.5 | Z5: 962.5 | AA5: 1059.5 | AB5: 161.5 | AC5: 208.5 | AD5: 899.5 | AE5: 889.5 | AF5: 148.5 | AG5: 174.5 | AH5: 908.5 | AI5: 902.5 | AJ5: 139.5 | AK5: 161.5 | AL5: 872.5 | AM5: 822.5 | AN5: 121.5 | AO5: 139.5 | AP5: 847.5 | AQ5: 827 | AR5: 130.5 | AS5: 135 | AT5: 827.5 | AU5: 769 | AV5: 130.5 | AW5: 135 | AX5: 783 | AY5: 743.5 | AZ5: 135 | BA5: 130.5 | BB5: 904 | BC5: 810 | BD5: 126 | BE5: 144 | BF5: 28.5278 | BG5: 77.2156 | BH5: =BB5 -> 904 | BI5: =BC5 -> 810 | BJ5: =(BH5-BI5) -> 94 | BK5: =(BJ5)/BI5*100 -> 11.604938 | BL5: =BD5 -> 126 | BM5: =BE5 -> 144 | BN5: =(BL5-BM5) -> -18 | BO5: =(BN5)/BM5*100 -> -12.5 | BP5: =K5+O5+R5+V5+Z5+AD5+AH5+AL5+AP5+AT5+AX5+BB5 -> 10678.5 | BQ5: =J5+N5+S5+W5+AA5+AE5+AI5+AM5+AQ5+AU5+Table1[[#This Row],[MS-0225]]+Table1[[#This Row],[MS-0325]] -> 10631.5 | BR5: =(BP5-BQ5) -> 47 | BS5: =(BR5)/BQ5*100 -> 0.44208249 | BT5: =M5+Q5+T5+X5+AB5+AF5+AJ5+AN5+AR5+AV5+AZ5+BD5 -> 1709.5 | BU5: =L5+P5+U5+Y5+AC5+AG5+AK5+AO5+AS5+AW5+BA5+BE5 -> 1964.5 | BV5: =(BT5-BU5) -> -255 | BW5: =(BV5)/BU5*100 -> -12.980402 | BX5: 0 | BY5: =BX5/BH5 -> 0 | BZ5: 0 | CA5: =BZ5/BP5 -> 0 | CB5: =BH5/SUMIFS(BH$2:BH$398,G$2:G$398,G5) -> 1 | CC5: =BI5/SUMIFS(BI$2:BI$398,G$2:G$398,G5) -> 1 | CD5: =CB5-CC5 -> 0 | CE5: =BL5/SUMIFS(BL$2:BL$398,G$2:G$398,G5) -> 1 | CF5: =BM5/SUMIFS(BM$2:BM$398,G$2:G$398,G5) -> 1 | CG5: =CE5-CF5 -> 0 | CH5: =BP5/SUMIFS(BP$2:BP$398,G$2:G$398,G5) -> 1 | CI5: =BQ5/SUMIFS(BQ$2:BQ$398,G$2:G$398,G5) -> 1 | CJ5: =CH5-CI5 -> 0 | CK5: =BT5/SUMIFS(BT$2:BT$398,G$2:G$398,G5) -> 1 | CL5: =BU5/SUMIFS(BU$2:BU$398,G$2:G$398,G5) -> 1 | CM5: =CK5-CL5 -> 0 | CN5: =COUNTIFS(G$2:G$398,G5)*CH5 -> 1 | CO5: =COUNTIFS(G$2:G$398,G5)*CK5 -> 1
A6: 112458 | B6: BPC | C6: VAIBHAV FILLING STATION | D6: VIKAS PURI DELHI | E6: WEST DELHI | F6: VAIBHAV-KARTIK-LAXMI | G6: VAIBHAV-KARTIK-LAXMI | H6: Punjabi Bagh | I6: Abhinav | J6: 800 | K6: 840 | L6: 100 | M6: 100 | N6: 860 | O6: 855 | P6: 140 | Q6: 105 | R6: 825 | S6: 835 | T6: 115 | U6: 145 | V6: 890 | W6: 845 | X6: 110 | Y6: 115 | Z6: 925 | AA6: 880 | AB6: 95 | AC6: 120 | AD6: 858 | AE6: 820 | AF6: 100 | AG6: 100 | AH6: 935 | AI6: 910 | AJ6: 105 | AK6: 130 | AL6: 820 | AM6: 790 | AN6: 100 | AO6: 90 | AP6: 840 | AQ6: 800 | AR6: 80 | AS6: 80 | AT6: 775 | AU6: 795 | AV6: 85 | AW6: 105 | AX6: 805 | AY6: 729 | AZ6: 95 | BA6: 85 | BB6: 860 | BC6: 820 | BD6: 100 | BE6: 100 | BF6: 28.63042 | BG6: 77.06826 | BH6: =BB6 -> 860 | BI6: =BC6 -> 820 | BJ6: =(BH6-BI6) -> 40 | BK6: =(BJ6)/BI6*100 -> 4.8780488 | BL6: =BD6 -> 100 | BM6: =BE6 -> 100 | BN6: =(BL6-BM6) -> 0 | BO6: =(BN6)/BM6*100 -> 0 | BP6: =K6+O6+R6+V6+Z6+AD6+AH6+AL6+AP6+AT6+AX6+BB6 -> 10228 | BQ6: =J6+N6+S6+W6+AA6+AE6+AI6+AM6+AQ6+AU6+Table1[[#This Row],[MS-0225]]+Table1[[#This Row],[MS-0325]] -> 9884 | BR6: =(BP6-BQ6) -> 344 | BS6: =(BR6)/BQ6*100 -> 3.4803723 | BT6: =M6+Q6+T6+X6+AB6+AF6+AJ6+AN6+AR6+AV6+AZ6+BD6 -> 1190 | BU6: =L6+P6+U6+Y6+AC6+AG6+AK6+AO6+AS6+AW6+BA6+BE6 -> 1310 | BV6: =(BT6-BU6) -> -120 | BW6: =(BV6)/BU6*100 -> -9.1603053 | BX6: 45 | BY6: =BX6/BH6 -> 0.052325581 | BZ6: 245 | CA6: =BZ6/BP6 -> 0.023953852 | CB6: =BH6/SUMIFS(BH$2:BH$398,G$2:G$398,G6) -> 0.34916768 | CC6: =BI6/SUMIFS(BI$2:BI$398,G$2:G$398,G6) -> 0.34775233 | CD6: =CB6-CC6 -> 0.0014153492 | CE6: =BL6/SUMIFS(BL$2:BL$398,G$2:G$398,G6) -> 0.38834951 | CF6: =BM6/SUMIFS(BM$2:BM$398,G$2:G$398,G6) -> 0.3125 | CG6: =CE6-CF6 -> 0.075849515 | CH6: =BP6/SUMIFS(BP$2:BP$398,G$2:G$398,G6) -> 0.34648283 | CI6: =BQ6/SUMIFS(BQ$2:BQ$398,G$2:G$398,G6) -> 0.34626636 | CJ6: =CH6-CI6 -> 0.00021647829 | CK6: =BT6/SUMIFS(BT$2:BT$398,G$2:G$398,G6) -> 0.34293948 | CL6: =BU6/SUMIFS(BU$2:BU$398,G$2:G$398,G6) -> 0.32639841 | CM6: =CK6-CL6 -> 0.016541076 | CN6: =COUNTIFS(G$2:G$398,G6)*CH6 -> 1.3859313 | CO6: =COUNTIFS(G$2:G$398,G6)*CK6 -> 1.3717579
A7: 112451 | B7: BPC | C7: SHIV SERVICE STATION | D7: DWARKA PURI DELHI | E7: SOUTH WEST DELHI | F7: SHIV SS | G7: SHIV SS | H7: Dwarka | I7: Raj Doshi | J7: 922.50001 | K7: 1015.5 | L7: 121.5 | M7: 130.5 | N7: 1063 | O7: 1008.5 | P7: 171 | Q7: 125.5 | R7: 937 | S7: 931.50001 | T7: 123 | U7: 148.5 | V7: 1008 | W7: 1011 | X7: 110 | Y7: 135 | Z7: 1014 | AA7: 918 | AB7: 122 | AC7: 144 | AD7: 994 | AE7: 984.5 | AF7: 110 | AG7: 121.5 | AH7: 974 | AI7: 957.5 | AJ7: 114 | AK7: 148.5 | AL7: 974 | AM7: 966.00001 | AN7: 106 | AO7: 108 | AP7: 960 | AQ7: 951 | AR7: 94 | AS7: 105 | AT7: 906 | AU7: 913 | AV7: 100 | AW7: 109 | AX7: 834 | AY7: 915.5 | AZ7: 102 | BA7: 126.5 | BB7: 853 | BC7: 928 | BD7: 87 | BE7: 126 | BF7: 28.59386 | BG7: 77.07785 | BH7: =BB7 -> 853 | BI7: =BC7 -> 928 | BJ7: =(BH7-BI7) -> -75 | BK7: =(BJ7)/BI7*100 -> -8.0818966 | BL7: =BD7 -> 87 | BM7: =BE7 -> 126 | BN7: =(BL7-BM7) -> -39 | BO7: =(BN7)/BM7*100 -> -30.952381 | BP7: =K7+O7+R7+V7+Z7+AD7+AH7+AL7+AP7+AT7+AX7+BB7 -> 11478 | BQ7: =J7+N7+S7+W7+AA7+AE7+AI7+AM7+AQ7+AU7+Table1[[#This Row],[MS-0225]]+Table1[[#This Row],[MS-0325]] -> 11461.5 | BR7: =(BP7-BQ7) -> 16.499972 | BS7: =(BR7)/BQ7*100 -> 0.14395997 | BT7: =M7+Q7+T7+X7+AB7+AF7+AJ7+AN7+AR7+AV7+AZ7+BD7 -> 1324 | BU7: =L7+P7+U7+Y7+AC7+AG7+AK7+AO7+AS7+AW7+BA7+BE7 -> 1564.5 | BV7: =(BT7-BU7) -> -240.5 | BW7: =(BV7)/BU7*100 -> -15.372323 | BX7: 60 | BY7: =BX7/BH7 -> 0.070339977 | BZ7: 279 | CA7: =BZ7/BP7 -> 0.024307371 | CB7: =BH7/SUMIFS(BH$2:BH$398,G$2:G$398,G7) -> 0.2233569 | CC7: =BI7/SUMIFS(BI$2:BI$398,G$2:G$398,G7) -> 0.25621204 | CD7: =CB7-CC7 -> -0.032855138 | CE7: =BL7/SUMIFS(BL$2:BL$398,G$2:G$398,G7) -> 0.16201117 | CF7: =BM7/SUMIFS(BM$2:BM$398,G$2:G$398,G7) -> 0.22105263 | CG7: =CE7-CF7 -> -0.059041458 | CH7: =BP7/SUMIFS(BP$2:BP$398,G$2:G$398,G7) -> 0.25405609 | CI7: =BQ7/SUMIFS(BQ$2:BQ$398,G$2:G$398,G7) -> 0.26239698 | CJ7: =CH7-CI7 -> -0.0083408905 | CK7: =BT7/SUMIFS(BT$2:BT$398,G$2:G$398,G7) -> 0.20652004 | CL7: =BU7/SUMIFS(BU$2:BU$398,G$2:G$398,G7) -> 0.22134975 | CM7: =CK7-CL7 -> -0.014829702 | CN7: =COUNTIFS(G$2:G$398,G7)*CH7 -> 1.7783926 | CO7: =COUNTIFS(G$2:G$398,G7)*CK7 -> 1.4456403
A8: 231764 | B8: IOC | C8: UNITED FUEL STATION | D8: PITAMPURA | E8: NORTH WEST DELHI | F8: White Patch- Inner Ring Road | G8: White Patch- Inner Ring Road | H8: Inner Ring Road | I8: Abhinav | J8: 164 | K8: 216 | L8: 196 | M8: 108 | N8: 189 | O8: 220 | P8: 201 | Q8: 128 | R8: 216 | S8: 204 | T8: 132 | U8: 180 | V8: 227 | W8: 201 | X8: 195 | Y8: 153 | Z8: 224 | AA8: 200 | AB8: 226 | AC8: 124 | AD8: 198.5 | AE8: 176 | AF8: 191.5 | AG8: 112 | AH8: 212 | AI8: 179 | AJ8: 212 | AK8: 151 | AL8: 197 | AM8: 192 | AN8: 195 | AO8: 96 | AP8: 194 | AQ8: 204 | AR8: 198 | AS8: 84 | AT8: 195 | AU8: 194 | AV8: 169 | AW8: 110 | AX8: 182 | AY8: 178 | AZ8: 182 | BA8: 118 | BB8: 188 | BC8: 204 | BD8: 218 | BE8: 120 | BF8: 28.6966 | BG8: 77.1554 | BH8: =BB8 -> 188 | BI8: =BC8 -> 204 | BJ8: =(BH8-BI8) -> -16 | BK8: =(BJ8)/BI8*100 -> -7.8431373 | BL8: =BD8 -> 218 | BM8: =BE8 -> 120 | BN8: =(BL8-BM8) -> 98 | BO8: =(BN8)/BM8*100 -> 81.666667 | BP8: =K8+O8+R8+V8+Z8+AD8+AH8+AL8+AP8+AT8+AX8+BB8 -> 2469.5 | BQ8: =J8+N8+S8+W8+AA8+AE8+AI8+AM8+AQ8+AU8+Table1[[#This Row],[MS-0225]]+Table1[[#This Row],[MS-0325]] -> 2285 | BR8: =(BP8-BQ8) -> 184.5 | BS8: =(BR8)/BQ8*100 -> 8.0743982 | BT8: =M8+Q8+T8+X8+AB8+AF8+AJ8+AN8+AR8+AV8+AZ8+BD8 -> 2154.5 | BU8: =L8+P8+U8+Y8+AC8+AG8+AK8+AO8+AS8+AW8+BA8+BE8 -> 1645 | BV8: =(BT8-BU8) -> 509.5 | BW8: =(BV8)/BU8*100 -> 30.972644 | BX8: 0 | BY8: =BX8/BH8 -> 0 | BZ8: 0 | CA8: =BZ8/BP8 -> 0 | CB8: =BH8/SUMIFS(BH$2:BH$398,G$2:G$398,G8) -> 0.077589765 | CC8: =BI8/SUMIFS(BI$2:BI$398,G$2:G$398,G8) -> 0.084384695 | CD8: =CB8-CC8 -> -0.0067949302 | CE8: =BL8/SUMIFS(BL$2:BL$398,G$2:G$398,G8) -> 0.2249742 | CF8: =BM8/SUMIFS(BM$2:BM$398,G$2:G$398,G8) -> 0.11412268 | CG8: =CE8-CF8 -> 0.11085152 | CH8: =BP8/SUMIFS(BP$2:BP$398,G$2:G$398,G8) -> 0.082125042 | CI8: =BQ8/SUMIFS(BQ$2:BQ$398,G$2:G$398,G8) -> 0.080480417 | CJ8: =CH8-CI8 -> 0.0016446246 | CK8: =BT8/SUMIFS(BT$2:BT$398,G$2:G$398,G8) -> 0.17182391 | CL8: =BU8/SUMIFS(BU$2:BU$398,G$2:G$398,G8) -> 0.12989577 | CM8: =CK8-CL8 -> 0.041928142 | CN8: =COUNTIFS(G$2:G$398,G8)*CH8 -> 0.49275025 | CO8: =COUNTIFS(G$2:G$398,G8)*CK8 -> 1.0309435
A9: 41056502 | B9: HPC | C9: INDRA FILLING STATION | D9: NARAINA | E9: NEW DELHI | F9: SYALL SS | G9: White Patch- Naraina | H9: Punjabi Bagh | I9: Abhinav | J9: 265 | K9: 284 | L9: 289 | M9: 574 | N9: 324 | O9: 317 | P9: 441 | Q9: 665 | R9: 314.5 | S9: 278 | T9: 643.5 | U9: 369 | V9: 321.5 | W9: 294.5 | X9: 569.5 | Y9: 516.5 | Z9: 326.5 | AA9: 317.5 | AB9: 570.5 | AC9: 567.5 | AD9: 331.5 | AE9: 315 | AF9: 703.5 | AG9: 592 | AH9: 313 | AI9: 322 | AJ9: 645 | AK9: 597 | AL9: 312.5 | AM9: 287 | AN9: 614.5 | AO9: 488 | AP9: 298 | AQ9: 291 | AR9: 787 | AS9: 521 | AT9: 304.5 | AU9: 295 | AV9: 613.5 | AW9: 594 | AX9: 281 | AY9: 255 | AZ9: 386 | BA9: 587 | BB9: 302.5 | BC9: 304 | BD9: 610.5 | BE9: 579 | BF9: 28.64191 | BG9: 77.14535 | BH9: =BB9 -> 302.5 | BI9: =BC9 -> 304 | BJ9: =(BH9-BI9) -> -1.5 | BK9: =(BJ9)/BI9*100 -> -0.49342105 | BL9: =BD9 -> 610.5 | BM9: =BE9 -> 579 | BN9: =(BL9-BM9) -> 31.5 | BO9: =(BN9)/BM9*100 -> 5.4404145 | BP9: =K9+O9+R9+V9+Z9+AD9+AH9+AL9+AP9+AT9+AX9+BB9 -> 3706.5 | BQ9: =J9+N9+S9+W9+AA9+AE9+AI9+AM9+AQ9+AU9+Table1[[#This Row],[MS-0225]]+Table1[[#This Row],[MS-0325]] -> 3548 | BR9: =(BP9-BQ9) -> 158.5 | BS9: =(BR9)/BQ9*100 -> 4.4673055 | BT9: =M9+Q9+T9+X9+AB9+AF9+AJ9+AN9+AR9+AV9+AZ9+BD9 -> 7382.5 | BU9: =L9+P9+U9+Y9+AC9+AG9+AK9+AO9+AS9+AW9+BA9+BE9 -> 6141 | BV9: =(BT9-BU9) -> 1241.5 | BW9: =(BV9)/BU9*100 -> 20.216577 | BX9: 0 | BY9: =BX9/BH9 -> 0 | BZ9: 0 | CA9: =BZ9/BP9 -> 0 | CB9: =BH9/SUMIFS(BH$2:BH$398,G$2:G$398,G9) -> 0.43872371 | CC9: =BI9/SUMIFS(BI$2:BI$398,G$2:G$398,G9) -> 0.39895013 | CD9: =CB9-CC9 -> 0.039773582 | CE9: =BL9/SUMIFS(BL$2:BL$398,G$2:G$398,G9) -> 0.70618855 | CF9: =BM9/SUMIFS(BM$2:BM$398,G$2:G$398,G9) -> 0.66475316 | CG9: =CE9-CF9 -> 0.041435391 | CH9: =BP9/SUMIFS(BP$2:BP$398,G$2:G$398,G9) -> 0.40565831 | CI9: =BQ9/SUMIFS(BQ$2:BQ$398,G$2:G$398,G9) -> 0.40993645 | CJ9: =CH9-CI9 -> -0.0042781406 | CK9: =BT9/SUMIFS(BT$2:BT$398,G$2:G$398,G9) -> 0.73210036 | CL9: =BU9/SUMIFS(BU$2:BU$398,G$2:G$398,G9) -> 0.64270016 | CM9: =CK9-CL9 -> 0.0894002 | CN9: =COUNTIFS(G$2:G$398,G9)*CH9 -> 0.81131662 | CO9: =COUNTIFS(G$2:G$398,G9)*CK9 -> 1.4642007 | CP9: =BD9-AZ9 -> 224.5
A10: 41056524 | B10: HPC | C10: ASSOCIATED SERVICE STATION | D10: SHAMNATH MARG | E10: CENTRAL DELHI | F10: RAJINDER-RS BHOLA | G10: RAJINDER-RS BHOLA | H10: Old Delhi | I10: Abhinav | J10: 144.5 | K10: 187 | L10: 438.5 | M10: 441 | N10: 172 | O10: 195 | P10: 512 | Q10: 513 | R10: 179.5 | S10: 117 | T10: 470.5 | U10: 483 | V10: 199 | W10: 148.5 | X10: 333 | Y10: 394.5 | Z10: 197 | AA10: 137.5 | AB10: 342 | AC10: 379.5 | AD10: 179 | AE10: 134 | AF10: 245 | AG10: 314 | AH10: 180 | AI10: 73 | AJ10: 289 | AK10: 339 | AL10: 182 | AM10: 109.5 | AN10: 301 | AO10: 317.5 | AP10: 179 | AQ10: 128 | AR10: 281 | AS10: 345 | AT10: 168 | AU10: 150 | AV10: 300 | AW10: 359 | AX10: 174 | AY10: 134 | AZ10: 328 | BA10: 449 | BB10: 185.5 | BC10: 169.5 | BD10: 379.5 | BE10: 445.5 | BF10: 28.67008 | BG10: 77.22636 | BH10: =BB10 -> 185.5 | BI10: =BC10 -> 169.5 | BJ10: =(BH10-BI10) -> 16 | BK10: =(BJ10)/BI10*100 -> 9.439528 | BL10: =BD10 -> 379.5 | BM10: =BE10 -> 445.5 | BN10: =(BL10-BM10) -> -66 | BO10: =(BN10)/BM10*100 -> -14.814815 | BP10: =K10+O10+R10+V10+Z10+AD10+AH10+AL10+AP10+AT10+AX10+BB10 -> 2205 | BQ10: =J10+N10+S10+W10+AA10+AE10+AI10+AM10+AQ10+AU10+Table1[[#This Row],[MS-0225]]+Table1[[#This Row],[MS-0325]] -> 1617.5 | BR10: =(BP10-BQ10) -> 587.5 | BS10: =(BR10)/BQ10*100 -> 36.321484 | BT10: =M10+Q10+T10+X10+AB10+AF10+AJ10+AN10+AR10+AV10+AZ10+BD10 -> 4223 | BU10: =L10+P10+U10+Y10+AC10+AG10+AK10+AO10+AS10+AW10+BA10+BE10 -> 4776.5 | BV10: =(BT10-BU10) -> -553.5 | BW10: =(BV10)/BU10*100 -> -11.587983 | BX10: 0 | BY10: =BX10/BH10 -> 0 | BZ10: 0 | CA10: =BZ10/BP10 -> 0 | CB10: =BH10/SUMIFS(BH$2:BH$398,G$2:G$398,G10) -> 0.2601683 | CC10: =BI10/SUMIFS(BI$2:BI$398,G$2:G$398,G10) -> 0.23722883 | CD10: =CB10-CC10 -> 0.022939472 | CE10: =BL10/SUMIFS(BL$2:BL$398,G$2:G$398,G10) -> 0.22833935 | CF10: =BM10/SUMIFS(BM$2:BM$398,G$2:G$398,G10) -> 0.28330684 | CG10: =CE10-CF10 -> -0.054967486 | CH10: =BP10/SUMIFS(BP$2:BP$398,G$2:G$398,G10) -> 0.24405091 | CI10: =BQ10/SUMIFS(BQ$2:BQ$398,G$2:G$398,G10) -> 0.18496284 | CJ10: =CH10-CI10 -> 0.059088077 | CK10: =BT10/SUMIFS(BT$2:BT$398,G$2:G$398,G10) -> 0.25549035 | CL10: =BU10/SUMIFS(BU$2:BU$398,G$2:G$398,G10) -> 0.27651384 | CM10: =CK10-CL10 -> -0.021023486 | CN10: =COUNTIFS(G$2:G$398,G10)*CH10 -> 0.73215274 | CO10: =COUNTIFS(G$2:G$398,G10)*CK10 -> 0.76647105 | CP10: =BD10-AZ10 -> 51.5
A11: 106336 | B11: IOC | C11: S VIDYA SERVICE STATION | D11: SEC-3, DWARKA | E11: SOUTH WEST DELHI | F11: SHIV SS | G11: SHIV SS | H11: Dwarka | I11: Raj Doshi | J11: 789.5 | K11: 800 | L11: 112.5 | M11: 100 | N11: 824.5 | O11: 825 | P11: 131.5 | Q11: 115 | R11: 780 | S11: 789 | T11: 114 | U11: 113 | V11: 805 | W11: 845 | X11: 115 | Y11: 115 | Z11: 830 | AA11: 850 | AB11: 90 | AC11: 110 | AD11: 800 | AE11: 805 | AF11: 100 | AG11: 113 | AH11: 854 | AI11: 870 | AJ11: 100 | AK11: 110 | AL11: 800 | AM11: 780 | AN11: 100 | AO11: 94 | AP11: 770 | AQ11: 765 | AR11: 70 | AS11: 95 | AT11: 745 | AU11: 758 | AV11: 95 | AW11: 100 | AX11: 740 | AY11: 699 | AZ11: 94 | BA11: 95 | BB11: 823 | BC11: 775 | BD11: 109 | BE11: 105 | BF11: 28.6048 | BG11: 77.0541 | BH11: =BB11 -> 823 | BI11: =BC11 -> 775 | BJ11: =(BH11-BI11) -> 48 | BK11: =(BJ11)/BI11*100 -> 6.1935484 | BL11: =BD11 -> 109 | BM11: =BE11 -> 105 | BN11: =(BL11-BM11) -> 4 | BO11: =(BN11)/BM11*100 -> 3.8095238 | BP11: =K11+O11+R11+V11+Z11+AD11+AH11+AL11+AP11+AT11+AX11+BB11 -> 9572 | BQ11: =J11+N11+S11+W11+AA11+AE11+AI11+AM11+AQ11+AU11+Table1[[#This Row],[MS-0225]]+Table1[[#This Row],[MS-0325]] -> 9550 | BR11: =(BP11-BQ11) -> 22 | BS11: =(BR11)/BQ11*100 -> 0.23036649 | BT11: =M11+Q11+T11+X11+AB11+AF11+AJ11+AN11+AR11+AV11+AZ11+BD11 -> 1202 | BU11: =L11+P11+U11+Y11+AC11+AG11+AK11+AO11+AS11+AW11+BA11+BE11 -> 1294 | BV11: =(BT11-BU11) -> -92 | BW11: =(BV11)/BU11*100 -> -7.1097372 | BX11: 0 | BY11: =BX11/BH11 -> 0 | BZ11: 0 | CA11: =BZ11/BP11 -> 0 | CB11: =BH11/SUMIFS(BH$2:BH$398,G$2:G$398,G11) -> 0.21550144 | CC11: =BI11/SUMIFS(BI$2:BI$398,G$2:G$398,G11) -> 0.21397018 | CD11: =CB11-CC11 -> 0.0015312579 | CE11: =BL11/SUMIFS(BL$2:BL$398,G$2:G$398,G11) -> 0.20297952 | CF11: =BM11/SUMIFS(BM$2:BM$398,G$2:G$398,G11) -> 0.18421053 | CG11: =CE11-CF11 -> 0.01876899 | CH11: =BP11/SUMIFS(BP$2:BP$398,G$2:G$398,G11) -> 0.21186835 | CI11: =BQ11/SUMIFS(BQ$2:BQ$398,G$2:G$398,G11) -> 0.21863553 | CJ11: =CH11-CI11 -> -0.0067671851 | CK11: =BT11/SUMIFS(BT$2:BT$398,G$2:G$398,G11) -> 0.18749025 | CL11: =BU11/SUMIFS(BU$2:BU$398,G$2:G$398,G11) -> 0.18307866 | CM11: =CK11-CL11 -> 0.0044115867 | CN11: =COUNTIFS(G$2:G$398,G11)*CH11 -> 1.4830784 | CO11: =COUNTIFS(G$2:G$398,G11)*CK11 -> 1.3124318
A12: 186866 | B12: IOC | C12: LOTUS AUTOMOBILES | D12: ANDHERIA MOR | E12: SOUTH DELHI | F12: White Patch_Chhatarpur_to_Gurgaon | G12: White Patch_Chhatarpur_to_Gurgaon | H12: Hauj Khas-Saket-Vasant Kunj | I12: Raj Doshi | J12: 658.5 | K12: 729 | L12: 235.5 | M12: 219 | N12: 719.5 | O12: 842.5 | P12: 256.5 | Q12: 275.5 | R12: 772.5 | S12: 688.5 | T12: 241.5 | U12: 277.5 | V12: 892 | W12: 719.5 | X12: 252 | Y12: 234.5 | Z12: 816.5 | AA12: 732.5 | AB12: 239.5 | AC12: 249.5 | AD12: 756.5 | AE12: 693 | AF12: 207.5 | AG12: 217 | AH12: 790.5 | AI12: 744 | AJ12: 217.5 | AK12: 222 | AL12: 741 | AM12: 646 | AN12: 187 | AO12: 186 | AP12: 746.5 | AQ12: 648 | AR12: 165.5 | AS12: 178 | AT12: 705.5 | AU12: 667 | AV12: 174.5 | AW12: 193 | AX12: 725 | AY12: 641 | AZ12: 173 | BA12: 181 | BB12: 809 | BC12: 680 | BD12: 221 | BE12: 190 | BF12: 28.5043 | BG12: 77.1721 | BH12: =BB12 -> 809 | BI12: =BC12 -> 680 | BJ12: =(BH12-BI12) -> 129 | BK12: =(BJ12)/BI12*100 -> 18.970588 | BL12: =BD12 -> 221 | BM12: =BE12 -> 190 | BN12: =(BL12-BM12) -> 31 | BO12: =(BN12)/BM12*100 -> 16.315789 | BP12: =K12+O12+R12+V12+Z12+AD12+AH12+AL12+AP12+AT12+AX12+BB12 -> 9326.5 | BQ12: =J12+N12+S12+W12+AA12+AE12+AI12+AM12+AQ12+AU12+Table1[[#This Row],[MS-0225]]+Table1[[#This Row],[MS-0325]] -> 8237.5 | BR12: =(BP12-BQ12) -> 1089 | BS12: =(BR12)/BQ12*100 -> 13.22003 | BT12: =M12+Q12+T12+X12+AB12+AF12+AJ12+AN12+AR12+AV12+AZ12+BD12 -> 2573.5 | BU12: =L12+P12+U12+Y12+AC12+AG12+AK12+AO12+AS12+AW12+BA12+BE12 -> 2620.5 | BV12: =(BT12-BU12) -> -47 | BW12: =(BV12)/BU12*100 -> -1.7935508 | BX12: 0 | BY12: =BX12/BH12 -> 0 | BZ12: 0 | CA12: =BZ12/BP12 -> 0 | CB12: =BH12/SUMIFS(BH$2:BH$398,G$2:G$398,G12) -> 0.57723867 | CC12: =BI12/SUMIFS(BI$2:BI$398,G$2:G$398,G12) -> 0.55578259 | CD12: =CB12-CC12 -> 0.021456082 | CE12: =BL12/SUMIFS(BL$2:BL$398,G$2:G$398,G12) -> 0.57477243 | CF12: =BM12/SUMIFS(BM$2:BM$398,G$2:G$398,G12) -> 0.49414824 | CG12: =CE12-CF12 -> 0.080624187 | CH12: =BP12/SUMIFS(BP$2:BP$398,G$2:G$398,G12) -> 0.58922197 | CI12: =BQ12/SUMIFS(BQ$2:BQ$398,G$2:G$398,G12) -> 0.55339088 | CJ12: =CH12-CI12 -> 0.035831089 | CK12: =BT12/SUMIFS(BT$2:BT$398,G$2:G$398,G12) -> 0.52525768 | CL12: =BU12/SUMIFS(BU$2:BU$398,G$2:G$398,G12) -> 0.50834142 | CM12: =CK12-CL12 -> 0.016916263 | CN12: =COUNTIFS(G$2:G$398,G12)*CH12 -> 1.1784439 | CO12: =COUNTIFS(G$2:G$398,G12)*CK12 -> 1.0505154
A13: 106289 | B13: IOC | C13: KOMAL and BROS. SERVICE STN. | D13: MANDAVALI, FAZALPUR | E13: EAST DELHI | F13: White Patch_Merrut Expressway | G13: White Patch_Merrut Expressway | H13: Mayur Vihar -Anand Vihar -Preet Vihar | I13: Bhanu Pratap | J13: 688.5 | K13: 717.5 | L13: 185.5 | M13: 166.5 | N13: 721.5 | O13: 748 | P13: 196.5 | Q13: 158 | R13: 758.5 | S13: 724 | T13: 145.5 | U13: 186 | V13: 759.5 | W13: 728 | X13: 150.5 | Y13: 196 | Z13: 759 | AA13: 714 | AB13: 147 | AC13: 186 | AD13: 710.5 | AE13: 675 | AF13: 157.5 | AG13: 157 | AH13: 774 | AI13: 714.5 | AJ13: 150 | AK13: 173.5 | AL13: 738 | AM13: 701.5 | AN13: 140 | AO13: 158.5 | AP13: 718 | AQ13: 700.5 | AR13: 132 | AS13: 135.5 | AT13: 685 | AU13: 692.5 | AV13: 145 | AW13: 153.5 | AX13: 693 | AY13: 665 | AZ13: 131 | BA13: 163 | BB13: 787 | BC13: 723.5 | BD13: 151 | BE13: 166.5 | BF13: 28.6292 | BG13: 77.3122 | BH13: =BB13 -> 787 | BI13: =BC13 -> 723.5 | BJ13: =(BH13-BI13) -> 63.5 | BK13: =(BJ13)/BI13*100 -> 8.7767795 | BL13: =BD13 -> 151 | BM13: =BE13 -> 166.5 | BN13: =(BL13-BM13) -> -15.5 | BO13: =(BN13)/BM13*100 -> -9.3093093 | BP13: =K13+O13+R13+V13+Z13+AD13+AH13+AL13+AP13+AT13+AX13+BB13 -> 8848 | BQ13: =J13+N13+S13+W13+AA13+AE13+AI13+AM13+AQ13+AU13+Table1[[#This Row],[MS-0225]]+Table1[[#This Row],[MS-0325]] -> 8448.5 | BR13: =(BP13-BQ13) -> 399.5 | BS13: =(BR13)/BQ13*100 -> 4.7286501 | BT13: =M13+Q13+T13+X13+AB13+AF13+AJ13+AN13+AR13+AV13+AZ13+BD13 -> 1774 | BU13: =L13+P13+U13+Y13+AC13+AG13+AK13+AO13+AS13+AW13+BA13+BE13 -> 2057.5 | BV13: =(BT13-BU13) -> -283.5 | BW13: =(BV13)/BU13*100 -> -13.778858 | BX13: 0 | BY13: =BX13/BH13 -> 0 | BZ13: 0 | CA13: =BZ13/BP13 -> 0 | CB13: =BH13/SUMIFS(BH$2:BH$398,G$2:G$398,G13) -> 0.42993718 | CC13: =BI13/SUMIFS(BI$2:BI$398,G$2:G$398,G13) -> 0.43323353 | CD13: =CB13-CC13 -> -0.0032963573 | CE13: =BL13/SUMIFS(BL$2:BL$398,G$2:G$398,G13) -> 0.39169909 | CF13: =BM13/SUMIFS(BM$2:BM$398,G$2:G$398,G13) -> 0.40609756 | CG13: =CE13-CF13 -> -0.014398469 | CH13: =BP13/SUMIFS(BP$2:BP$398,G$2:G$398,G13) -> 0.42185563 | CI13: =BQ13/SUMIFS(BQ$2:BQ$398,G$2:G$398,G13) -> 0.42498554 | CJ13: =CH13-CI13 -> -0.0031299071 | CK13: =BT13/SUMIFS(BT$2:BT$398,G$2:G$398,G13) -> 0.37857448 | CL13: =BU13/SUMIFS(BU$2:BU$398,G$2:G$398,G13) -> 0.40466123 | CM13: =CK13-CL13 -> -0.026086748 | CN13: =COUNTIFS(G$2:G$398,G13)*CH13 -> 2.1092782 | CO13: =COUNTIFS(G$2:G$398,G13)*CK13 -> 1.8928724
A14: 106270 | B14: IOC | C14: IMAGE FILLING STATION | D14: MAYUR VIHAR, PHASE-I | E14: EAST DELHI | F14: White Patch_Noida Link road to Greater Noida Expwy | G14: White Patch_Noida Link road to Greater Noida Expwy | H14: Mayur Vihar -Anand Vihar -Preet Vihar | I14: Bhanu Pratap | J14: 707.5 | K14: 761 | L14: 194.5 | M14: 173 | N14: 755.5 | O14: 803 | P14: 208.5 | Q14: 173 | R14: 757 | S14: 735.5 | T14: 159 | U14: 192.5 | V14: 791.5 | W14: 765.5 | X14: 154.5 | Y14: 184.5 | Z14: 790 | AA14: 781.5 | AB14: 162 | AC14: 202.5 | AD14: 755 | AE14: 735.5 | AF14: 185 | AG14: 184.5 | AH14: 782.5 | AI14: 779.5 | AJ14: 233.5 | AK14: 196.5 | AL14: 723.5 | AM14: 710.5 | AN14: 168.5 | AO14: 155.5 | AP14: 708 | AQ14: 721.5 | AR14: 148 | AS14: 152.5 | AT14: 690 | AU14: 696 | AV14: 130 | AW14: 160 | AX14: 678 | AY14: 655 | AZ14: 138 | BA14: 179 | BB14: 770 | BC14: 745.5 | BD14: 150 | BE14: 166.5 | BF14: 28.5937 | BG14: 77.2968 | BH14: =BB14 -> 770 | BI14: =BC14 -> 745.5 | BJ14: =(BH14-BI14) -> 24.5 | BK14: =(BJ14)/BI14*100 -> 3.286385 | BL14: =BD14 -> 150 | BM14: =BE14 -> 166.5 | BN14: =(BL14-BM14) -> -16.5 | BO14: =(BN14)/BM14*100 -> -9.9099099 | BP14: =K14+O14+R14+V14+Z14+AD14+AH14+AL14+AP14+AT14+AX14+BB14 -> 9009.5 | BQ14: =J14+N14+S14+W14+AA14+AE14+AI14+AM14+AQ14+AU14+Table1[[#This Row],[MS-0225]]+Table1[[#This Row],[MS-0325]] -> 8789 | BR14: =(BP14-BQ14) -> 220.5 | BS14: =(BR14)/BQ14*100 -> 2.5088178 | BT14: =M14+Q14+T14+X14+AB14+AF14+AJ14+AN14+AR14+AV14+AZ14+BD14 -> 1974.5 | BU14: =L14+P14+U14+Y14+AC14+AG14+AK14+AO14+AS14+AW14+BA14+BE14 -> 2177 | BV14: =(BT14-BU14) -> -202.5 | BW14: =(BV14)/BU14*100 -> -9.3017915 | BX14: 0 | BY14: =BX14/BH14 -> 0 | BZ14: 0 | CA14: =BZ14/BP14 -> 0 | CB14: =BH14/SUMIFS(BH$2:BH$398,G$2:G$398,G14) -> 1 | CC14: =BI14/SUMIFS(BI$2:BI$398,G$2:G$398,G14) -> 1 | CD14: =CB14-CC14 -> 0 | CE14: =BL14/SUMIFS(BL$2:BL$398,G$2:G$398,G14) -> 1 | CF14: =BM14/SUMIFS(BM$2:BM$398,G$2:G$398,G14) -> 1 | CG14: =CE14-CF14 -> 0 | CH14: =BP14/SUMIFS(BP$2:BP$398,G$2:G$398,G14) -> 1 | CI14: =BQ14/SUMIFS(BQ$2:BQ$398,G$2:G$398,G14) -> 1 | CJ14: =CH14-CI14 -> 0 | CK14: =BT14/SUMIFS(BT$2:BT$398,G$2:G$398,G14) -> 1 | CL14: =BU14/SUMIFS(BU$2:BU$398,G$2:G$398,G14) -> 1 | CM14: =CK14-CL14 -> 0 | CN14: =COUNTIFS(G$2:G$398,G14)*CH14 -> 1 | CO14: =COUNTIFS(G$2:G$398,G14)*CK14 -> 1
A15: 186860 | B15: IOC | C15: SATBIR FILLING STATION | D15: IGI MOR | E15: NEW DELHI | F15: White Patch_IGI_NH8 | G15: White Patch_IGI_NH8 | H15: Dwarka | I15: Raj Doshi | J15: 729 | K15: 765 | L15: 279 | M15: 255 | N15: 791 | O15: 800 | P15: 301 | Q15: 260 | R15: 755 | S15: 787.5 | T15: 245 | U15: 310.5 | V15: 835 | W15: 765 | X15: 265 | Y15: 297 | Z15: 795 | AA15: 805.5 | AB15: 245 | AC15: 292.5 | AD15: 755 | AE15: 706.5 | AF15: 245 | AG15: 265.5 | AH15: 795 | AI15: 711 | AJ15: 245 | AK15: 261 | AL15: 750 | AM15: 630 | AN15: 210 | AO15: 216 | AP15: 740 | AQ15: 679.5 | AR15: 180 | AS15: 202.5 | AT15: 720 | AU15: 666 | AV15: 200 | AW15: 216 | AX15: 705 | AY15: 630 | AZ15: 215 | BA15: 216 | BB15: 770 | BC15: 733 | BD15: 210 | BE15: 233 | BF15: 28.5336 | BG15: 77.1069 | BH15: =BB15 -> 770 | BI15: =BC15 -> 733 | BJ15: =(BH15-BI15) -> 37 | BK15: =(BJ15)/BI15*100 -> 5.047749 | BL15: =BD15 -> 210 | BM15: =BE15 -> 233 | BN15: =(BL15-BM15) -> -23 | BO15: =(BN15)/BM15*100 -> -9.8712446 | BP15: =K15+O15+R15+V15+Z15+AD15+AH15+AL15+AP15+AT15+AX15+BB15 -> 9185 | BQ15: =J15+N15+S15+W15+AA15+AE15+AI15+AM15+AQ15+AU15+Table1[[#This Row],[MS-0225]]+Table1[[#This Row],[MS-0325]] -> 8634 | BR15: =(BP15-BQ15) -> 551 | BS15: =(BR15)/BQ15*100 -> 6.3817466 | BT15: =M15+Q15+T15+X15+AB15+AF15+AJ15+AN15+AR15+AV15+AZ15+BD15 -> 2775 | BU15: =L15+P15+U15+Y15+AC15+AG15+AK15+AO15+AS15+AW15+BA15+BE15 -> 3090 | BV15: =(BT15-BU15) -> -315 | BW15: =(BV15)/BU15*100 -> -10.194175 | BX15: 0 | BY15: =BX15/BH15 -> 0 | BZ15: 0 | CA15: =BZ15/BP15 -> 0 | CB15: =BH15/SUMIFS(BH$2:BH$398,G$2:G$398,G15) -> 1 | CC15: =BI15/SUMIFS(BI$2:BI$398,G$2:G$398,G15) -> 1 | CD15: =CB15-CC15 -> 0 | CE15: =BL15/SUMIFS(BL$2:BL$398,G$2:G$398,G15) -> 1 | CF15: =BM15/SUMIFS(BM$2:BM$398,G$2:G$398,G15) -> 1 | CG15: =CE15-CF15 -> 0 | CH15: =BP15/SUMIFS(BP$2:BP$398,G$2:G$398,G15) -> 1 | CI15: =BQ15/SUMIFS(BQ$2:BQ$398,G$2:G$398,G15) -> 1 | CJ15: =CH15-CI15 -> 0 | CK15: =BT15/SUMIFS(BT$2:BT$398,G$2:G$398,G15) -> 1 | CL15: =BU15/SUMIFS(BU$2:BU$398,G$2:G$398,G15) -> 1 | CM15: =CK15-CL15 -> 0 | CN15: =COUNTIFS(G$2:G$398,G15)*CH15 -> 1 | CO15: =COUNTIFS(G$2:G$398,G15)*CK15 -> 1
A16: 112397 | B16: BPC | C16: BUDH SINGH GULAB SINGH | D16: MEHRAULI ROAD DELHI | E16: SOUTH DELHI | F16: BSGS | G16: BSGS | H16: Hauj Khas-Saket-Vasant Kunj | I16: Raj Doshi | J16: 634.5 | K16: 642 | L16: 193.5 | M16: 180 | N16: 684 | O16: 693 | P16: 252 | Q16: 225 | R16: 652.5 | S16: 639 | T16: 175.5 | U16: 207 | V16: 729 | W16: 711 | X16: 189 | Y16: 225 | Z16: 715.5 | AA16: 679.5 | AB16: 184.5 | AC16: 238.5 | AD16: 724.5 | AE16: 688.5 | AF16: 211.5 | AG16: 193.5 | AH16: 717 | AI16: 697.5 | AJ16: 195 | AK16: 220.5 | AL16: 675 | AM16: 616.5 | AN16: 165 | AO16: 193.5 | AP16: 685 | AQ16: 607.5 | AR16: 135 | AS16: 166.5 | AT16: 625 | AU16: 621 | AV16: 175 | AW16: 171 | AX16: 650 | AY16: 578 | AZ16: 170 | BA16: 180 | BB16: 760 | BC16: 639 | BD16: 220 | BE16: 207 | BF16: 28.52799 | BG16: 77.18981 | BH16: =BB16 -> 760 | BI16: =BC16 -> 639 | BJ16: =(BH16-BI16) -> 121 | BK16: =(BJ16)/BI16*100 -> 18.935837 | BL16: =BD16 -> 220 | BM16: =BE16 -> 207 | BN16: =(BL16-BM16) -> 13 | BO16: =(BN16)/BM16*100 -> 6.2801932 | BP16: =K16+O16+R16+V16+Z16+AD16+AH16+AL16+AP16+AT16+AX16+BB16 -> 8268.5 | BQ16: =J16+N16+S16+W16+AA16+AE16+AI16+AM16+AQ16+AU16+Table1[[#This Row],[MS-0225]]+Table1[[#This Row],[MS-0325]] -> 7796 | BR16: =(BP16-BQ16) -> 472.49999 | BS16: =(BR16)/BQ16*100 -> 6.0608003 | BT16: =M16+Q16+T16+X16+AB16+AF16+AJ16+AN16+AR16+AV16+AZ16+BD16 -> 2225.5 | BU16: =L16+P16+U16+Y16+AC16+AG16+AK16+AO16+AS16+AW16+BA16+BE16 -> 2448 | BV16: =(BT16-BU16) -> -222.5 | BW16: =(BV16)/BU16*100 -> -9.0890523 | BX16: 143.5 | BY16: =BX16/BH16 -> 0.18881579 | BZ16: 809.5 | CA16: =BZ16/BP16 -> 0.097901675 | CB16: =BH16/SUMIFS(BH$2:BH$398,G$2:G$398,G16) -> 0.46270928 | CC16: =BI16/SUMIFS(BI$2:BI$398,G$2:G$398,G16) -> 0.42150396 | CD16: =CB16-CC16 -> 0.041205327 | CE16: =BL16/SUMIFS(BL$2:BL$398,G$2:G$398,G16) -> 0.5398773 | CF16: =BM16/SUMIFS(BM$2:BM$398,G$2:G$398,G16) -> 0.4579646 | CG16: =CE16-CF16 -> 0.081912699 | CH16: =BP16/SUMIFS(BP$2:BP$398,G$2:G$398,G16) -> 0.42974455 | CI16: =BQ16/SUMIFS(BQ$2:BQ$398,G$2:G$398,G16) -> 0.42520931 | CJ16: =CH16-CI16 -> 0.0045352442 | CK16: =BT16/SUMIFS(BT$2:BT$398,G$2:G$398,G16) -> 0.48238864 | CL16: =BU16/SUMIFS(BU$2:BU$398,G$2:G$398,G16) -> 0.45552661 | CM16: =CK16-CL16 -> 0.026862032 | CN16: =COUNTIFS(G$2:G$398,G16)*CH16 -> 1.2892336 | CO16: =COUNTIFS(G$2:G$398,G16)*CK16 -> 1.4471659
A17: 112720 | B17: BPC | C17: MASIH AUTOMOBILES | D17: ANAND VIHAR,NEW DELHI | E17: SHAHDARA | F17: ALLIED_MASIH | G17: ALLIED_MASIH | H17: Mayur Vihar -Anand Vihar -Preet Vihar | I17: Bhanu Pratap | J17: 697 | K17: 770.5 | L17: 203 | M17: 183.5 | N17: 769 | O17: 772 | P17: 221 | Q17: 204 | R17: 707 | S17: 707.5 | T17: 175 | U17: 228.5 | V17: 834 | W17: 809 | X17: 200 | Y17: 217 | Z17: 781 | AA17: 772.5 | AB17: 187 | AC17: 217.5 | AD17: 737 | AE17: 732.5 | AF17: 165 | AG17: 203.5 | AH17: 768 | AI17: 755 | AJ17: 178 | AK17: 199 | AL17: 693 | AM17: 686 | AN17: 165 | AO17: 160 | AP17: 703 | AQ17: 694 | AR17: 155 | AS17: 152 | AT17: 659 | AU17: 622.5 | AV17: 155 | AW17: 169.5 | AX17: 644 | AY17: 639 | AZ17: 148 | BA17: 153 | BB17: 754 | BC17: 706 | BD17: 170 | BE17: 176 | BF17: 28.65808 | BG17: 77.31086 | BH17: =BB17 -> 754 | BI17: =BC17 -> 706 | BJ17: =(BH17-BI17) -> 48 | BK17: =(BJ17)/BI17*100 -> 6.7988669 | BL17: =BD17 -> 170 | BM17: =BE17 -> 176 | BN17: =(BL17-BM17) -> -6 | BO17: =(BN17)/BM17*100 -> -3.4090909 | BP17: =K17+O17+R17+V17+Z17+AD17+AH17+AL17+AP17+AT17+AX17+BB17 -> 8822.5 | BQ17: =J17+N17+S17+W17+AA17+AE17+AI17+AM17+AQ17+AU17+Table1[[#This Row],[MS-0225]]+Table1[[#This Row],[MS-0325]] -> 8590 | BR17: =(BP17-BQ17) -> 232.5 | BS17: =(BR17)/BQ17*100 -> 2.7066356 | BT17: =M17+Q17+T17+X17+AB17+AF17+AJ17+AN17+AR17+AV17+AZ17+BD17 -> 2085.5 | BU17: =L17+P17+U17+Y17+AC17+AG17+AK17+AO17+AS17+AW17+BA17+BE17 -> 2300 | BV17: =(BT17-BU17) -> -214.5 | BW17: =(BV17)/BU17*100 -> -9.326087 | BX17: 64 | BY17: =BX17/BH17 -> 0.084880637 | BZ17: 397.5 | CA17: =BZ17/BP17 -> 0.045055256 | CB17: =BH17/SUMIFS(BH$2:BH$398,G$2:G$398,G17) -> 0.18258869 | CC17: =BI17/SUMIFS(BI$2:BI$398,G$2:G$398,G17) -> 0.18603426 | CD17: =CB17-CC17 -> -0.0034455645 | CE17: =BL17/SUMIFS(BL$2:BL$398,G$2:G$398,G17) -> 0.26666667 | CF17: =BM17/SUMIFS(BM$2:BM$398,G$2:G$398,G17) -> 0.26268657 | CG17: =CE17-CF17 -> 0.0039800995 | CH17: =BP17/SUMIFS(BP$2:BP$398,G$2:G$398,G17) -> 0.17973267 | CI17: =BQ17/SUMIFS(BQ$2:BQ$398,G$2:G$398,G17) -> 0.18768777 | CJ17: =CH17-CI17 -> -0.0079550998 | CK17: =BT17/SUMIFS(BT$2:BT$398,G$2:G$398,G17) -> 0.26873449 | CL17: =BU17/SUMIFS(BU$2:BU$398,G$2:G$398,G17) -> 0.27198335 | CM17: =CK17-CL17 -> -0.0032488603 | CN17: =COUNTIFS(G$2:G$398,G17)*CH17 -> 1.4378614 | CO17: =COUNTIFS(G$2:G$398,G17)*CK17 -> 2.1498759
A18: 41056494 | B18: HPC | C18: SHANTI SERVICE STATION | D18: MADANPUR KHADAR | E18: SOUTH EAST DELHI | F18: AUTO REST_OKHLA | G18: AUTO REST_OKHLA | H18: Mathura Road | I18: Bhanu Pratap | J18: 610 | K18: 691 | L18: 216 | M18: 230 | N18: 688 | O18: 746 | P18: 246 | Q18: 239 | R18: 680 | S18: 558 | T18: 200 | U18: 211 | V18: 743 | W18: 575.5 | X18: 215 | Y18: 201.5 | Z18: 757 | AA18: 659.5 | AB18: 203 | AC18: 217.5 | AD18: 705 | AE18: 609.5 | AF18: 218 | AG18: 218.5 | AH18: 729 | AI18: 675 | AJ18: 205 | AK18: 245 | AL18: 739.5 | AM18: 733 | AN18: 204.5 | AO18: 208 | AP18: 746.5 | AQ18: 670 | AR18: 163.5 | AS18: 182 | AT18: 726 | AU18: 651 | AV18: 196 | AW18: 175 | AX18: 699.5 | AY18: 649 | AZ18: 202.5 | BA18: 200 | BB18: 733 | BC18: 714 | BD18: 184 | BE18: 230 | BF18: 28.52094 | BG18: 77.29476 | BH18: =BB18 -> 733 | BI18: =BC18 -> 714 | BJ18: =(BH18-BI18) -> 19 | BK18: =(BJ18)/BI18*100 -> 2.6610644 | BL18: =BD18 -> 184 | BM18: =BE18 -> 230 | BN18: =(BL18-BM18) -> -46 | BO18: =(BN18)/BM18*100 -> -20 | BP18: =K18+O18+R18+V18+Z18+AD18+AH18+AL18+AP18+AT18+AX18+BB18 -> 8695.5 | BQ18: =J18+N18+S18+W18+AA18+AE18+AI18+AM18+AQ18+AU18+Table1[[#This Row],[MS-0225]]+Table1[[#This Row],[MS-0325]] -> 7792.5 | BR18: =(BP18-BQ18) -> 903 | BS18: =(BR18)/BQ18*100 -> 11.588065 | BT18: =M18+Q18+T18+X18+AB18+AF18+AJ18+AN18+AR18+AV18+AZ18+BD18 -> 2460.5 | BU18: =L18+P18+U18+Y18+AC18+AG18+AK18+AO18+AS18+AW18+BA18+BE18 -> 2550.5 | BV18: =(BT18-BU18) -> -90 | BW18: =(BV18)/BU18*100 -> -3.5287199 | BX18: 0 | BY18: =BX18/BH18 -> 0 | BZ18: 0 | CA18: =BZ18/BP18 -> 0 | CB18: =BH18/SUMIFS(BH$2:BH$398,G$2:G$398,G18) -> 0.13315168 | CC18: =BI18/SUMIFS(BI$2:BI$398,G$2:G$398,G18) -> 0.13675541 | CD18: =CB18-CC18 -> -0.0036037306 | CE18: =BL18/SUMIFS(BL$2:BL$398,G$2:G$398,G18) -> 0.12786657 | CF18: =BM18/SUMIFS(BM$2:BM$398,G$2:G$398,G18) -> 0.14790997 | CG18: =CE18-CF18 -> -0.020043394 | CH18: =BP18/SUMIFS(BP$2:BP$398,G$2:G$398,G18) -> 0.13540385 | CI18: =BQ18/SUMIFS(BQ$2:BQ$398,G$2:G$398,G18) -> 0.12217301 | CJ18: =CH18-CI18 -> 0.013230843 | CK18: =BT18/SUMIFS(BT$2:BT$398,G$2:G$398,G18) -> 0.13705994 | CL18: =BU18/SUMIFS(BU$2:BU$398,G$2:G$398,G18) -> 0.12203349 | CM18: =CK18-CL18 -> 0.015026445 | CN18: =COUNTIFS(G$2:G$398,G18)*CH18 -> 1.4894424 | CO18: =COUNTIFS(G$2:G$398,G18)*CK18 -> 1.5076593
A19: 112441 | B19: BPC | C19: RAJDHANI SERVICE STN.(CC 112441) | D19: SHAHDARA DELHI | E19: EAST DELHI | F19: MATTA | G19: MATTA | H19: Mayur Vihar -Anand Vihar -Preet Vihar | I19: Bhanu Pratap | J19: 640 | K19: 697.5 | L19: 280 | M19: 310.5 | N19: 702 | O19: 706.5 | P19: 270 | Q19: 337.5 | R19: 688.5 | S19: 657 | T19: 319.5 | U19: 333 | V19: 703.5 | W19: 670.5 | X19: 306.5 | Y19: 373.5 | Z19: 715.5 | AA19: 688.5 | AB19: 274.5 | AC19: 337.5 | AD19: 684 | AE19: 666 | AF19: 324 | AG19: 342 | AH19: 706.5 | AI19: 711 | AJ19: 349.5 | AK19: 387 | AL19: 675 | AM19: 652.5 | AN19: 315 | AO19: 355.5 | AP19: 643.5 | AQ19: 655.5 | AR19: 274.5 | AS19: 292.5 | AT19: 652.5 | AU19: 643.5 | AV19: 277.5 | AW19: 328.5 | AX19: 625.5 | AY19: 630 | AZ19: 292.5 | BA19: 342 | BB19: 706.5 | BC19: 666 | BD19: 301.5 | BE19: 324 | BF19: 28.625687 | BG19: 77.313728 | BH19: =BB19 -> 706.5 | BI19: =BC19 -> 666 | BJ19: =(BH19-BI19) -> 40.5 | BK19: =(BJ19)/BI19*100 -> 6.0810811 | BL19: =BD19 -> 301.5 | BM19: =BE19 -> 324 | BN19: =(BL19-BM19) -> -22.5 | BO19: =(BN19)/BM19*100 -> -6.9444444 | BP19: =K19+O19+R19+V19+Z19+AD19+AH19+AL19+AP19+AT19+AX19+BB19 -> 8205 | BQ19: =J19+N19+S19+W19+AA19+AE19+AI19+AM19+AQ19+AU19+Table1[[#This Row],[MS-0225]]+Table1[[#This Row],[MS-0325]] -> 7982.5 | BR19: =(BP19-BQ19) -> 222.5 | BS19: =(BR19)/BQ19*100 -> 2.7873473 | BT19: =M19+Q19+T19+X19+AB19+AF19+AJ19+AN19+AR19+AV19+AZ19+BD19 -> 3683 | BU19: =L19+P19+U19+Y19+AC19+AG19+AK19+AO19+AS19+AW19+BA19+BE19 -> 3965.5 | BV19: =(BT19-BU19) -> -282.5 | BW19: =(BV19)/BU19*100 -> -7.123944 | BX19: 0 | BY19: =BX19/BH19 -> 0 | BZ19: 0 | CA19: =BZ19/BP19 -> 0 | CB19: =BH19/SUMIFS(BH$2:BH$398,G$2:G$398,G19) -> 0.3087175 | CC19: =BI19/SUMIFS(BI$2:BI$398,G$2:G$398,G19) -> 0.30762125 | CD19: =CB19-CC19 -> 0.0010962534 | CE19: =BL19/SUMIFS(BL$2:BL$398,G$2:G$398,G19) -> 0.30074813 | CF19: =BM19/SUMIFS(BM$2:BM$398,G$2:G$398,G19) -> 0.35801105 | CG19: =CE19-CF19 -> -0.05726292 | CH19: =BP19/SUMIFS(BP$2:BP$398,G$2:G$398,G19) -> 0.29285791 | CI19: =BQ19/SUMIFS(BQ$2:BQ$398,G$2:G$398,G19) -> 0.30104465 | CJ19: =CH19-CI19 -> -0.0081867446 | CK19: =BT19/SUMIFS(BT$2:BT$398,G$2:G$398,G19) -> 0.31698081 | CL19: =BU19/SUMIFS(BU$2:BU$398,G$2:G$398,G19) -> 0.31199843 | CM19: =CK19-CL19 -> 0.0049823809 | CN19: =COUNTIFS(G$2:G$398,G19)*CH19 -> 1.7571474 | CO19: =COUNTIFS(G$2:G$398,G19)*CK19 -> 1.9018848
A20: 106287 | B20: IOC | C20: KHYBER SERVICE STATION | D20: RING ROAD, MOTI BAGH | E20: NEW DELHI | F20: White Patch_Moti Bagh | G20: White Patch_Moti Bagh | H20: Inner Ring Road | I20: Bhanu Pratap | J20: 614 | K20: 751 | L20: 314 | M20: 305 | N20: 704.5 | O20: 753 | P20: 299.5 | Q20: 303 | R20: 734.5 | S20: 706 | T20: 279.5 | U20: 310 | V20: 767 | W20: 704 | X20: 285 | Y20: 314 | Z20: 800.5 | AA20: 702 | AB20: 281.5 | AC20: 328 | AD20: 711.5 | AE20: 708 | AF20: 270.5 | AG20: 324 | AH20: 751 | AI20: 702 | AJ20: 279 | AK20: 270 | AL20: 752 | AM20: 738 | AN20: 270 | AO20: 260 | AP20: 651 | AQ20: 701.5 | AR20: 263 | AS20: 250.5 | AT20: 670 | AU20: 652 | AV20: 290 | AW20: 290 | AX20: 684 | AY20: 670 | AZ20: 290 | BA20: 270 | BB20: 700 | BC20: 750 | BD20: 408 | BE20: 308 | BF20: 28.5874 | BG20: 77.1713 | BH20: =BB20 -> 700 | BI20: =BC20 -> 750 | BJ20: =(BH20-BI20) -> -50 | BK20: =(BJ20)/BI20*100 -> -6.6666667 | BL20: =BD20 -> 408 | BM20: =BE20 -> 308 | BN20: =(BL20-BM20) -> 100 | BO20: =(BN20)/BM20*100 -> 32.467532 | BP20: =K20+O20+R20+V20+Z20+AD20+AH20+AL20+AP20+AT20+AX20+BB20 -> 8725.5 | BQ20: =J20+N20+S20+W20+AA20+AE20+AI20+AM20+AQ20+AU20+Table1[[#This Row],[MS-0225]]+Table1[[#This Row],[MS-0325]] -> 8352 | BR20: =(BP20-BQ20) -> 373.5 | BS20: =(BR20)/BQ20*100 -> 4.4719828 | BT20: =M20+Q20+T20+X20+AB20+AF20+AJ20+AN20+AR20+AV20+AZ20+BD20 -> 3524.5 | BU20: =L20+P20+U20+Y20+AC20+AG20+AK20+AO20+AS20+AW20+BA20+BE20 -> 3538 | BV20: =(BT20-BU20) -> -13.5 | BW20: =(BV20)/BU20*100 -> -0.38157151 | BX20: 0 | BY20: =BX20/BH20 -> 0 | BZ20: 0 | CA20: =BZ20/BP20 -> 0 | CB20: =BH20/SUMIFS(BH$2:BH$398,G$2:G$398,G20) -> 0.49928673 | CC20: =BI20/SUMIFS(BI$2:BI$398,G$2:G$398,G20) -> 0.5179558 | CD20: =CB20-CC20 -> -0.018669068 | CE20: =BL20/SUMIFS(BL$2:BL$398,G$2:G$398,G20) -> 0.64353312 | CF20: =BM20/SUMIFS(BM$2:BM$398,G$2:G$398,G20) -> 0.47678019 | CG20: =CE20-CF20 -> 0.16675294 | CH20: =BP20/SUMIFS(BP$2:BP$398,G$2:G$398,G20) -> 0.50299764 | CI20: =BQ20/SUMIFS(BQ$2:BQ$398,G$2:G$398,G20) -> 0.4969358 | CJ20: =CH20-CI20 -> 0.0060618359 | CK20: =BT20/SUMIFS(BT$2:BT$398,G$2:G$398,G20) -> 0.47596219 | CL20: =BU20/SUMIFS(BU$2:BU$398,G$2:G$398,G20) -> 0.46467034 | CM20: =CK20-CL20 -> 0.011291844 | CN20: =COUNTIFS(G$2:G$398,G20)*CH20 -> 1.5089929 | CO20: =COUNTIFS(G$2:G$398,G20)*CK20 -> 1.4278866
A21: 106344 | B21: IOC | C21: SENANI SERVICE STATION | D21: SECTOR-23, ROHINI | E21: NORTH WEST DELHI | F21: White Patch- Rohini | G21: ROHINI_SANJEEV | H21: Rohini | I21: Abhinav | J21: 669 | K21: 742.5 | L21: 165 | M21: 139.5 | N21: 728.5 | O21: 755 | P21: 177.5 | Q21: 141 | R21: 701.5 | S21: 689 | T21: 158.5 | U21: 175 | V21: 793 | W21: 748.5 | X21: 149 | Y21: 175.5 | Z21: 759 | AA21: 753.5 | AB21: 149 | AC21: 172.5 | AD21: 737 | AE21: 713 | AF21: 159 | AG21: 169 | AH21: 816 | AI21: 753.5 | AJ21: 144 | AK21: 188.5 | AL21: 727 | AM21: 706.5 | AN21: 145 | AO21: 121.5 | AP21: 717 | AQ21: 690.5 | AR21: 135 | AS21: 119.5 | AT21: 717 | AU21: 684.5 | AV21: 167 | AW21: 173.5 | AX21: 725 | AY21: 676.5 | AZ21: 163 | BA21: 157.5 | BB21: 831.5 | BC21: 729.5 | BD21: 222.5 | BE21: 134.5 | BF21: 28.7183 | BG21: 77.0711 | BH21: =BB21 -> 831.5 | BI21: =BC21 -> 729.5 | BJ21: =(BH21-BI21) -> 102 | BK21: =(BJ21)/BI21*100 -> 13.98218 | BL21: =BD21 -> 222.5 | BM21: =BE21 -> 134.5 | BN21: =(BL21-BM21) -> 88 | BO21: =(BN21)/BM21*100 -> 65.427509 | BP21: =K21+O21+R21+V21+Z21+AD21+AH21+AL21+AP21+AT21+AX21+BB21 -> 9021.5 | BQ21: =J21+N21+S21+W21+AA21+AE21+AI21+AM21+AQ21+AU21+Table1[[#This Row],[MS-0225]]+Table1[[#This Row],[MS-0325]] -> 8542.5 | BR21: =(BP21-BQ21) -> 479 | BS21: =(BR21)/BQ21*100 -> 5.6072578 | BT21: =M21+Q21+T21+X21+AB21+AF21+AJ21+AN21+AR21+AV21+AZ21+BD21 -> 1872.5 | BU21: =L21+P21+U21+Y21+AC21+AG21+AK21+AO21+AS21+AW21+BA21+BE21 -> 1929.5 | BV21: =(BT21-BU21) -> -57 | BW21: =(BV21)/BU21*100 -> -2.9541332 | BX21: 0 | BY21: =BX21/BH21 -> 0 | BZ21: 0 | CA21: =BZ21/BP21 -> 0 | CB21: =BH21/SUMIFS(BH$2:BH$398,G$2:G$398,G21) -> 0.32652661 | CC21: =BI21/SUMIFS(BI$2:BI$398,G$2:G$398,G21) -> 0.37162506 | CD21: =CB21-CC21 -> -0.045098459 | CE21: =BL21/SUMIFS(BL$2:BL$398,G$2:G$398,G21) -> 0.5771725 | CF21: =BM21/SUMIFS(BM$2:BM$398,G$2:G$398,G21) -> 0.44684385 | CG21: =CE21-CF21 -> 0.13032865 | CH21: =BP21/SUMIFS(BP$2:BP$398,G$2:G$398,G21) -> 0.3230907 | CI21: =BQ21/SUMIFS(BQ$2:BQ$398,G$2:G$398,G21) -> 0.32827992 | CJ21: =CH21-CI21 -> -0.0051892194 | CK21: =BT21/SUMIFS(BT$2:BT$398,G$2:G$398,G21) -> 0.46194647 | CL21: =BU21/SUMIFS(BU$2:BU$398,G$2:G$398,G21) -> 0.44002281 | CM21: =CK21-CL21 -> 0.021923661 | CN21: =COUNTIFS(G$2:G$398,G21)*CH21 -> 2.2616349 | CO21: =COUNTIFS(G$2:G$398,G21)*CK21 -> 3.2336253
A22: 234809 | B22: IOC | C22: SHRI SAI FILLING STATION | D22: PUNJAB KHOD, DELHI | E22: NORTH WEST DELHI | F22: PUNJABKHOR | G22: PUNJABKHOR | H22: Punjabkhor | I22: Abhinav | J22: 76 | K22: 76 | L22: 92 | M22: 92 | N22: 80 | O22: 84 | P22: 88 | Q22: 84 | R22: 76 | S22: 76 | T22: 80 | U22: 68 | V22: 92 | W22: 84 | X22: 76 | Y22: 96 | Z22: 80 | AA22: 77.5 | AB22: 64 | AC22: 60.5 | AD22: 76 | AE22: 79.5 | AF22: 128 | AG22: 104.5 | AH22: 88 | AI22: 74 | AJ22: 104 | AK22: 130 | AL22: 80 | AM22: 92 | AN22: 76 | AO22: 88 | AP22: 72 | AQ22: 67 | AR22: 60 | AS22: 55 | AT22: 76 | AU22: 76.5 | AV22: 68 | AW22: 61.5 | AX22: 72 | AY22: 64 | AZ22: 60 | BA22: 68 | BB22: 80 | BC22: 77 | BD22: 136 | BE22: 73 | BF22: 28.7667 | BG22: 76.9647 | BH22: =BB22 -> 80 | BI22: =BC22 -> 77 | BJ22: =(BH22-BI22) -> 3 | BK22: =(BJ22)/BI22*100 -> 3.8961039 | BL22: =BD22 -> 136 | BM22: =BE22 -> 73 | BN22: =(BL22-BM22) -> 63 | BO22: =(BN22)/BM22*100 -> 86.30137 | BP22: =K22+O22+R22+V22+Z22+AD22+AH22+AL22+AP22+AT22+AX22+BB22 -> 952 | BQ22: =J22+N22+S22+W22+AA22+AE22+AI22+AM22+AQ22+AU22+Table1[[#This Row],[MS-0225]]+Table1[[#This Row],[MS-0325]] -> 923.5 | BR22: =(BP22-BQ22) -> 28.5 | BS22: =(BR22)/BQ22*100 -> 3.0860855 | BT22: =M22+Q22+T22+X22+AB22+AF22+AJ22+AN22+AR22+AV22+AZ22+BD22 -> 1028 | BU22: =L22+P22+U22+Y22+AC22+AG22+AK22+AO22+AS22+AW22+BA22+BE22 -> 984.5 | BV22: =(BT22-BU22) -> 43.5 | BW22: =(BV22)/BU22*100 -> 4.4184865 | BX22: 0 | BY22: =BX22/BH22 -> 0 | BZ22: 0 | CA22: =BZ22/BP22 -> 0 | CB22: =BH22/SUMIFS(BH$2:BH$398,G$2:G$398,G22) -> 0.76923077 | CC22: =BI22/SUMIFS(BI$2:BI$398,G$2:G$398,G22) -> 0.70642202 | CD22: =CB22-CC22 -> 0.062808751 | CE22: =BL22/SUMIFS(BL$2:BL$398,G$2:G$398,G22) -> 0.91891892 | CF22: =BM22/SUMIFS(BM$2:BM$398,G$2:G$398,G22) -> 0.72277228 | CG22: =CE22-CF22 -> 0.19614664 | CH22: =BP22/SUMIFS(BP$2:BP$398,G$2:G$398,G22) -> 0.73769857 | CI22: =BQ22/SUMIFS(BQ$2:BQ$398,G$2:G$398,G22) -> 0.74898621 | CJ22: =CH22-CI22 -> -0.011287646 | CK22: =BT22/SUMIFS(BT$2:BT$398,G$2:G$398,G22) -> 0.84021251 | CL22: =BU22/SUMIFS(BU$2:BU$398,G$2:G$398,G22) -> 0.79845904 | CM22: =CK22-CL22 -> 0.041753462 | CN22: =COUNTIFS(G$2:G$398,G22)*CH22 -> 1.4753971 | CO22: =COUNTIFS(G$2:G$398,G22)*CK22 -> 1.680425
... A55: 107629 | B55: IOC | C55: DELHI AUTOMOBILES LTD | D55: SARITA VIHAR | E55: SOUTH EAST DELHI | F55: AUTO REST_OKHLA | G55: AUTO REST_OKHLA | H55: Okhla | I55: Bhanu Pratap | J55: 553.5 | K55: 513 | L55: 220.5 | M55: 153 | N55: 603 | O55: 558 | P55: 225 | Q55: 162 | R55: 526.5 | S55: 625.5 | T55: 139.5 | U55: 220.5 | V55: 553.5 | W55: 608 | X55: 148.5 | Y55: 216 | Z55: 558 | AA55: 612 | AB55: 144 | AC55: 198 | AD55: 504 | AE55: 545 | AF55: 144 | AG55: 189 | AH55: 549 | AI55: 627.5 | AJ55: 171 | AK55: 202.5 | AL55: 558 | AM55: 553.5 | AN55: 162 | AO55: 148.5 | AP55: 522 | AQ55: 497 | AR55: 144 | AS55: 153 | AT55: 508.5 | AU55: 506 | AV55: 139.5 | AW55: 144 | AX55: 513 | AY55: 524 | AZ55: 153 | BA55: 162 | BB55: 562.5 | BC55: 485.5 | BD55: 139.5 | BE55: 148.5 | BF55: 28.5381 | BG55: 77.2902 | BH55: =BB55 -> 562.5 | BI55: =BC55 -> 485.5 | BJ55: =(BH55-BI55) -> 77 | BK55: =(BJ55)/BI55*100 -> 15.859938 | BL55: =BD55 -> 139.5 | BM55: =BE55 -> 148.5 | BN55: =(BL55-BM55) -> -9 | BO55: =(BN55)/BM55*100 -> -6.0606061 | BP55: =K55+O55+R55+V55+Z55+AD55+AH55+AL55+AP55+AT55+AX55+BB55 -> 6426 | BQ55: =J55+N55+S55+W55+AA55+AE55+AI55+AM55+AQ55+AU55+Table1[[#This Row],[MS-0225]]+Table1[[#This Row],[MS-0325]] -> 6740.5 | BR55: =(BP55-BQ55) -> -314.5 | BS55: =(BR55)/BQ55*100 -> -4.665826 | BT55: =M55+Q55+T55+X55+AB55+AF55+AJ55+AN55+AR55+AV55+AZ55+BD55 -> 1800 | BU55: =L55+P55+U55+Y55+AC55+AG55+AK55+AO55+AS55+AW55+BA55+BE55 -> 2227.5 | BV55: =(BT55-BU55) -> -427.5 | BW55: =(BV55)/BU55*100 -> -19.191919 | BX55: 0 | BY55: =BX55/BH55 -> 0 | BZ55: 0 | CA55: =BZ55/BP55 -> 0 | CB55: =BH55/SUMIFS(BH$2:BH$398,G$2:G$398,G55) -> 0.10217984 | CC55: =BI55/SUMIFS(BI$2:BI$398,G$2:G$398,G55) -> 0.092989849 | CD55: =CB55-CC55 -> 0.0091899878 | CE55: =BL55/SUMIFS(BL$2:BL$398,G$2:G$398,G55) -> 0.096942321 | CF55: =BM55/SUMIFS(BM$2:BM$398,G$2:G$398,G55) -> 0.095498392 | CG55: =CE55-CF55 -> 0.0014439288 | CH55: =BP55/SUMIFS(BP$2:BP$398,G$2:G$398,G55) -> 0.10006384 | CI55: =BQ55/SUMIFS(BQ$2:BQ$398,G$2:G$398,G55) -> 0.10567946 | CJ55: =CH55-CI55 -> -0.0056156134 | CK55: =BT55/SUMIFS(BT$2:BT$398,G$2:G$398,G55) -> 0.10026738 | CL55: =BU55/SUMIFS(BU$2:BU$398,G$2:G$398,G55) -> 0.10657895 | CM55: =CK55-CL55 -> -0.0063115677 | CN55: =COUNTIFS(G$2:G$398,G55)*CH55 -> 1.1007023 | CO55: =COUNTIFS(G$2:G$398,G55)*CK55 -> 1.1029412
A56: 41056544 | B56: HPC | C56: NARAYAN SERVICE STATION | D56: KHYBER PASS | E56: CENTRAL DELHI | F56: RAJINDER-RS BHOLA | G56: White Patch- Naraina | H56: Ashok Vihar | I56: Abhinav | J56: 326 | K56: 446 | L56: 310 | M56: 301 | N56: 403 | O56: 486.5 | P56: 279 | Q56: 273.5 | R56: 451 | S56: 449 | T56: 314 | U56: 294 | V56: 489.5 | W56: 437 | X56: 212.5 | Y56: 202 | Z56: 507.5 | AA56: 457.5 | AB56: 198.5 | AC56: 265.5 | AD56: 492 | AE56: 442 | AF56: 184 | AG56: 264 | AH56: 492 | AI56: 477 | AJ56: 201 | AK56: 297 | AL56: 476 | AM56: 430 | AN56: 179 | AO56: 346 | AP56: 443 | AQ56: 420 | AR56: 182 | AS56: 280 | AT56: 365 | AU56: 392.5 | AV56: 195 | AW56: 266.5 | AX56: 395 | AY56: 415 | AZ56: 207 | BA56: 318 | BB56: 387 | BC56: 458 | BD56: 254 | BE56: 292 | BF56: 28.69301 | BG56: 77.22077 | BH56: =BB56 -> 387 | BI56: =BC56 -> 458 | BJ56: =(BH56-BI56) -> -71 | BK56: =(BJ56)/BI56*100 -> -15.502183 | BL56: =BD56 -> 254 | BM56: =BE56 -> 292 | BN56: =(BL56-BM56) -> -38 | BO56: =(BN56)/BM56*100 -> -13.013699 | BP56: =K56+O56+R56+V56+Z56+AD56+AH56+AL56+AP56+AT56+AX56+BB56 -> 5430.5 | BQ56: =J56+N56+S56+W56+AA56+AE56+AI56+AM56+AQ56+AU56+Table1[[#This Row],[MS-0225]]+Table1[[#This Row],[MS-0325]] -> 5107 | BR56: =(BP56-BQ56) -> 323.5 | BS56: =(BR56)/BQ56*100 -> 6.3344429 | BT56: =M56+Q56+T56+X56+AB56+AF56+AJ56+AN56+AR56+AV56+AZ56+BD56 -> 2701.5 | BU56: =L56+P56+U56+Y56+AC56+AG56+AK56+AO56+AS56+AW56+BA56+BE56 -> 3414 | BV56: =(BT56-BU56) -> -712.5 | BW56: =(BV56)/BU56*100 -> -20.869947 | BX56: 0 | BY56: =BX56/BH56 -> 0 | BZ56: 0 | CA56: =BZ56/BP56 -> 0 | CB56: =BH56/SUMIFS(BH$2:BH$398,G$2:G$398,G56) -> 0.56127629 | CC56: =BI56/SUMIFS(BI$2:BI$398,G$2:G$398,G56) -> 0.60104987 | CD56: =CB56-CC56 -> -0.039773582 | CE56: =BL56/SUMIFS(BL$2:BL$398,G$2:G$398,G56) -> 0.29381145 | CF56: =BM56/SUMIFS(BM$2:BM$398,G$2:G$398,G56) -> 0.33524684 | CG56: =CE56-CF56 -> -0.041435391 | CH56: =BP56/SUMIFS(BP$2:BP$398,G$2:G$398,G56) -> 0.59434169 | CI56: =BQ56/SUMIFS(BQ$2:BQ$398,G$2:G$398,G56) -> 0.59006355 | CJ56: =CH56-CI56 -> 0.0042781406 | CK56: =BT56/SUMIFS(BT$2:BT$398,G$2:G$398,G56) -> 0.26789964 | CL56: =BU56/SUMIFS(BU$2:BU$398,G$2:G$398,G56) -> 0.35729984 | CM56: =CK56-CL56 -> -0.0894002 | CN56: =COUNTIFS(G$2:G$398,G56)*CH56 -> 1.1886834 | CO56: =COUNTIFS(G$2:G$398,G56)*CK56 -> 0.53579929 | CP56: =BD56-AZ56 -> 47
A57: 41019252 | B57: HPC | C57: BHARAT HP CENTRE | D57: DWARKA(COMM.ON31.03.09) | E57: SOUTH WEST DELHI | F57: BS DWARKA | G57: BS DWARKA | H57: Dwarka | I57: Raj Doshi | J57: 463.5 | K57: 536 | L57: 112.5 | M57: 103 | N57: 522 | O57: 560 | P57: 126 | Q57: 122 | R57: 550 | S57: 495 | T57: 110 | U57: 117 | V57: 599 | W57: 567 | X57: 105 | Y57: 117 | Z57: 594 | AA57: 563 | AB57: 106 | AC57: 117 | AD57: 561 | AE57: 531 | AF57: 104 | AG57: 117 | AH57: 583 | AI57: 576 | AJ57: 99 | AK57: 126 | AL57: 547 | AM57: 514.5 | AN57: 91 | AO57: 88.5 | AP57: 527 | AQ57: 487 | AR57: 89 | AS57: 81 | AT57: 518 | AU57: 491 | AV57: 98 | AW57: 103 | AX57: 504 | AY57: 481 | AZ57: 90 | BA57: 91 | BB57: 557 | BC57: 529 | BD57: 105 | BE57: 109 | BF57: 28.593462 | BG57: 77.043284 | BH57: =BB57 -> 557 | BI57: =BC57 -> 529 | BJ57: =(BH57-BI57) -> 28 | BK57: =(BJ57)/BI57*100 -> 5.2930057 | BL57: =BD57 -> 105 | BM57: =BE57 -> 109 | BN57: =(BL57-BM57) -> -4 | BO57: =(BN57)/BM57*100 -> -3.6697248 | BP57: =K57+O57+R57+V57+Z57+AD57+AH57+AL57+AP57+AT57+AX57+BB57 -> 6636 | BQ57: =J57+N57+S57+W57+AA57+AE57+AI57+AM57+AQ57+AU57+Table1[[#This Row],[MS-0225]]+Table1[[#This Row],[MS-0325]] -> 6220 | BR57: =(BP57-BQ57) -> 416 | BS57: =(BR57)/BQ57*100 -> 6.6881029 | BT57: =M57+Q57+T57+X57+AB57+AF57+AJ57+AN57+AR57+AV57+AZ57+BD57 -> 1222 | BU57: =L57+P57+U57+Y57+AC57+AG57+AK57+AO57+AS57+AW57+BA57+BE57 -> 1305 | BV57: =(BT57-BU57) -> -83 | BW57: =(BV57)/BU57*100 -> -6.3601533 | BX57: 0 | BY57: =BX57/BH57 -> 0 | BZ57: 0 | CA57: =BZ57/BP57 -> 0 | CB57: =BH57/SUMIFS(BH$2:BH$398,G$2:G$398,G57) -> 0.32048331 | CC57: =BI57/SUMIFS(BI$2:BI$398,G$2:G$398,G57) -> 0.34417697 | CD57: =CB57-CC57 -> -0.023693654 | CE57: =BL57/SUMIFS(BL$2:BL$398,G$2:G$398,G57) -> 0.32407407 | CF57: =BM57/SUMIFS(BM$2:BM$398,G$2:G$398,G57) -> 0.35737705 | CG57: =CE57-CF57 -> -0.033302975 | CH57: =BP57/SUMIFS(BP$2:BP$398,G$2:G$398,G57) -> 0.33434099 | CI57: =BQ57/SUMIFS(BQ$2:BQ$398,G$2:G$398,G57) -> 0.34437893 | CJ57: =CH57-CI57 -> -0.010037936 | CK57: =BT57/SUMIFS(BT$2:BT$398,G$2:G$398,G57) -> 0.33188485 | CL57: =BU57/SUMIFS(BU$2:BU$398,G$2:G$398,G57) -> 0.34693606 | CM57: =CK57-CL57 -> -0.015051218 | CN57: =COUNTIFS(G$2:G$398,G57)*CH57 -> 1.337364 | CO57: =COUNTIFS(G$2:G$398,G57)*CK57 -> 1.3275394
A58: 106315 | B58: IOC | C58: PRAGATI | D58: MINTO ROAD | E58: CENTRAL DELHI | F58: KRISHNA-RAIZADA | G58: KRISHNA-RAIZADA | H58: Old Delhi | I58: Abhinav | J58: 148.5 | K58: 171 | L58: 31.5 | M58: 27 | N58: 148.5 | O58: 175.5 | P58: 31.5 | Q58: 22.5 | R58: 171 | S58: 144 | T58: 27 | U58: 36 | V58: 171 | W58: 173 | X58: 45 | Y58: 45 | Z58: 189 | AA58: 156 | AB58: 45 | AC58: 28 | AD58: 180 | AE58: 154 | AF58: 36 | AG58: 28 | AH58: 171 | AI58: 174 | AJ58: 45 | AK58: 32 | AL58: 180 | AM58: 173 | AN58: 72 | AO58: 45 | AP58: 171 | AQ58: 162 | AR58: 27 | AS58: 30 | AT58: 171 | AU58: 157.5 | AV58: 27 | AW58: 22.5 | AX58: 180 | AY58: 126 | AZ58: 36 | BA58: 36 | BB58: 171 | BC58: 169.5 | BD58: 63 | BE58: 22.5 | BF58: 28.6413 | BG58: 77.2289 | BH58: =BB58 -> 171 | BI58: =BC58 -> 169.5 | BJ58: =(BH58-BI58) -> 1.5 | BK58: =(BJ58)/BI58*100 -> 0.88495575 | BL58: =BD58 -> 63 | BM58: =BE58 -> 22.5 | BN58: =(BL58-BM58) -> 40.5 | BO58: =(BN58)/BM58*100 -> 180 | BP58: =K58+O58+R58+V58+Z58+AD58+AH58+AL58+AP58+AT58+AX58+BB58 -> 2101.5 | BQ58: =J58+N58+S58+W58+AA58+AE58+AI58+AM58+AQ58+AU58+Table1[[#This Row],[MS-0225]]+Table1[[#This Row],[MS-0325]] -> 1886 | BR58: =(BP58-BQ58) -> 215.5 | BS58: =(BR58)/BQ58*100 -> 11.426299 | BT58: =M58+Q58+T58+X58+AB58+AF58+AJ58+AN58+AR58+AV58+AZ58+BD58 -> 472.5 | BU58: =L58+P58+U58+Y58+AC58+AG58+AK58+AO58+AS58+AW58+BA58+BE58 -> 388 | BV58: =(BT58-BU58) -> 84.5 | BW58: =(BV58)/BU58*100 -> 21.778351 | BX58: 0 | BY58: =BX58/BH58 -> 0 | BZ58: 0 | CA58: =BZ58/BP58 -> 0 | CB58: =BH58/SUMIFS(BH$2:BH$398,G$2:G$398,G58) -> 0.11902135 | CC58: =BI58/SUMIFS(BI$2:BI$398,G$2:G$398,G58) -> 0.1202764 | CD58: =CB58-CC58 -> -0.0012550494 | CE58: =BL58/SUMIFS(BL$2:BL$398,G$2:G$398,G58) -> 0.16392206 | CF58: =BM58/SUMIFS(BM$2:BM$398,G$2:G$398,G58) -> 0.06846939 | CG58: =CE58-CF58 -> 0.095452667 | CH58: =BP58/SUMIFS(BP$2:BP$398,G$2:G$398,G58) -> 0.12183884 | CI58: =BQ58/SUMIFS(BQ$2:BQ$398,G$2:G$398,G58) -> 0.11522902 | CJ58: =CH58-CI58 -> 0.0066098253 | CK58: =BT58/SUMIFS(BT$2:BT$398,G$2:G$398,G58) -> 0.11621512 | CL58: =BU58/SUMIFS(BU$2:BU$398,G$2:G$398,G58) -> 0.097411515 | CM58: =CK58-CL58 -> 0.018803606 | CN58: =COUNTIFS(G$2:G$398,G58)*CH58 -> 0.73103306 | CO58: =COUNTIFS(G$2:G$398,G58)*CK58 -> 0.69729072
